Workbook

Sheet Template
A1: Status On Plan Work Shop
A2: ลำดับ | B2: วันที่ | C2: JOB | D2: DWG.Name | E2: จำนวนชิ้น | F2: เสร็จแล้ว | G2: ยังไม่เสร็จ | H2: สถานะ | I2: PROCESS | J2: ผู้รับผิดชอบ | K2: เวลา/ช.ม/นาที | L2: PROCESS | M2: ผู้รับผิดชอบ | N2: เวลา/ช.ม/นาที | O2: PROCESS | P2: ผู้รับผิดชอบ | Q2: เวลา/ช.ม/นาที | R2: PROCESS | S2: ผู้รับผิดชอบ | T2: เวลา/ช.ม/นาที | U2: เวลารวม | V2: OUTSOURCE | Y2: ผู้ส่งแบบ | Z2: กำหนดส่ง | AA2: วันเสร็จจริง | AB2: ผู้รับ | AC2: วันที่รับ | AD2: KPI ส่งมอบ | AE2: แก้ไข(ชิ้น) | AG2: ราคาแมท ขึ้นใหม่ | AH2: Remark
A3: ลำดับ | B3: วันที่ | C3: JOB | D3: DWG.Name | E3: จำนวนชิ้น | F3: เสร็จแล้ว | G3: ยังไม่เสร็จ | H3: สถานะ | I3: PROCESS | J3: ผู้รับผิดชอบ | K3: เวลา/ช.ม/นาที | L3: PROCESS | M3: ผู้รับผิดชอบ | N3: เวลา/ช.ม/นาที | O3: PROCESS | P3: ผู้รับผิดชอบ | Q3: เวลา/ช.ม/นาที | R3: PROCESS | S3: ผู้รับผิดชอบ | T3: เวลา/ช.ม/นาที | U3: เวลารวม | V3: Process | W3: Process | X3: Coating /Heat Treatment | Y3: ผู้ส่งแบบ | Z3: กำหนดส่ง | AA3: วันเสร็จจริง | AB3: ผู้รับ | AC3: วันที่รับ | AE3: แก้ไขได้ | AF3: ขึ้นใหม่
A4: 1 | G4: =$E4-$F4 -> 0 | H4: =IF($G4=0,"ครบ","ไม่ครบ") -> ครบ | J4: =VLOOKUP(I4,Sheet2!$B$1:$C$9,2,FALSE) -> #N/A | M4: =VLOOKUP(L4,Sheet2!$B$1:$C$9,2,FALSE) -> #N/A | P4: =VLOOKUP(O4,Sheet2!$B$1:$C$9,2,FALSE) -> #N/A | S4: =VLOOKUP(R4,Sheet2!$B$1:$C$9,2,FALSE) -> #N/A | U4: =$K4+$N4+$Q4+$T4 -> 0 | AD4: =IF($AA4>$Z4,"เกินกำหนด","ทันกำหนด") -> ทันกำหนด
A5: 2 | G5: =$E5-$F5 -> 0 | H5: =IF($G5=0,"ครบ","ไม่ครบ") -> ครบ | J5: =VLOOKUP(I5,Sheet2!$B$1:$C$9,2,FALSE) -> #N/A | M5: =VLOOKUP(L5,Sheet2!$B$1:$C$9,2,FALSE) -> #N/A | P5: =VLOOKUP(O5,Sheet2!$B$1:$C$9,2,FALSE) -> #N/A | S5: =VLOOKUP(R5,Sheet2!$B$1:$C$9,2,FALSE) -> #N/A | U5: =$K5+$N5+$Q5+$T5 -> 0 | AD5: =IF($AA5>$Z5,"เกินกำหนด","ทันกำหนด") -> ทันกำหนด
A6: 3 | G6: =$E6-$F6 -> 0 | H6: =IF($G6=0,"ครบ","ไม่ครบ") -> ครบ | J6: =VLOOKUP(I6,Sheet2!$B$1:$C$9,2,FALSE) -> #N/A | M6: =VLOOKUP(L6,Sheet2!$B$1:$C$9,2,FALSE) -> #N/A | P6: =VLOOKUP(O6,Sheet2!$B$1:$C$9,2,FALSE) -> #N/A | S6: =VLOOKUP(R6,Sheet2!$B$1:$C$9,2,FALSE) -> #N/A | U6: =$K6+$N6+$Q6+$T6 -> 0 | AD6: =IF($AA6>$Z6,"เกินกำหนด","ทันกำหนด") -> ทันกำหนด
A7: 4 | G7: =$E7-$F7 -> 0 | H7: =IF($G7=0,"ครบ","ไม่ครบ") -> ครบ | J7: =VLOOKUP(I7,Sheet2!$B$1:$C$9,2,FALSE) -> #N/A | M7: =VLOOKUP(L7,Sheet2!$B$1:$C$9,2,FALSE) -> #N/A | P7: =VLOOKUP(O7,Sheet2!$B$1:$C$9,2,FALSE) -> #N/A | S7: =VLOOKUP(R7,Sheet2!$B$1:$C$9,2,FALSE) -> #N/A | U7: =$K7+$N7+$Q7+$T7 -> 0 | AD7: =IF($AA7>$Z7,"เกินกำหนด","ทันกำหนด") -> ทันกำหนด
A8: 5 | G8: =$E8-$F8 -> 0 | H8: =IF($G8=0,"ครบ","ไม่ครบ") -> ครบ | J8: =VLOOKUP(I8,Sheet2!$B$1:$C$9,2,FALSE) -> #N/A | M8: =VLOOKUP(L8,Sheet2!$B$1:$C$9,2,FALSE) -> #N/A | P8: =VLOOKUP(O8,Sheet2!$B$1:$C$9,2,FALSE) -> #N/A | S8: =VLOOKUP(R8,Sheet2!$B$1:$C$9,2,FALSE) -> #N/A | U8: =$K8+$N8+$Q8+$T8 -> 0 | AD8: =IF($AA8>$Z8,"เกินกำหนด","ทันกำหนด") -> ทันกำหนด
A9: 6 | G9: =$E9-$F9 -> 0 | H9: =IF($G9=0,"ครบ","ไม่ครบ") -> ครบ | J9: =VLOOKUP(I9,Sheet2!$B$1:$C$9,2,FALSE) -> #N/A | M9: =VLOOKUP(L9,Sheet2!$B$1:$C$9,2,FALSE) -> #N/A | P9: =VLOOKUP(O9,Sheet2!$B$1:$C$9,2,FALSE) -> #N/A | S9: =VLOOKUP(R9,Sheet2!$B$1:$C$9,2,FALSE) -> #N/A | U9: =$K9+$N9+$Q9+$T9 -> 0 | AD9: =IF($AA9>$Z9,"เกินกำหนด","ทันกำหนด") -> ทันกำหนด
A10: 7 | G10: =$E10-$F10 -> 0 | H10: =IF($G10=0,"ครบ","ไม่ครบ") -> ครบ | J10: =VLOOKUP(I10,Sheet2!$B$1:$C$9,2,FALSE) -> #N/A | M10: =VLOOKUP(L10,Sheet2!$B$1:$C$9,2,FALSE) -> #N/A | P10: =VLOOKUP(O10,Sheet2!$B$1:$C$9,2,FALSE) -> #N/A | S10: =VLOOKUP(R10,Sheet2!$B$1:$C$9,2,FALSE) -> #N/A | U10: =$K10+$N10+$Q10+$T10 -> 0 | AD10: =IF($AA10>$Z10,"เกินกำหนด","ทันกำหนด") -> ทันกำหนด
A11: 8 | G11: =$E11-$F11 -> 0 | H11: =IF($G11=0,"ครบ","ไม่ครบ") -> ครบ | J11: =VLOOKUP(I11,Sheet2!$B$1:$C$9,2,FALSE) -> #N/A | M11: =VLOOKUP(L11,Sheet2!$B$1:$C$9,2,FALSE) -> #N/A | P11: =VLOOKUP(O11,Sheet2!$B$1:$C$9,2,FALSE) -> #N/A | S11: =VLOOKUP(R11,Sheet2!$B$1:$C$9,2,FALSE) -> #N/A | U11: =$K11+$N11+$Q11+$T11 -> 0 | AD11: =IF($AA11>$Z11,"เกินกำหนด","ทันกำหนด") -> ทันกำหนด
A12: 9 | G12: =$E12-$F12 -> 0 | H12: =IF($G12=0,"ครบ","ไม่ครบ") -> ครบ | J12: =VLOOKUP(I12,Sheet2!$B$1:$C$9,2,FALSE) -> #N/A | M12: =VLOOKUP(L12,Sheet2!$B$1:$C$9,2,FALSE) -> #N/A | P12: =VLOOKUP(O12,Sheet2!$B$1:$C$9,2,FALSE) -> #N/A | S12: =VLOOKUP(R12,Sheet2!$B$1:$C$9,2,FALSE) -> #N/A | U12: =$K12+$N12+$Q12+$T12 -> 0 | AD12: =IF($AA12>$Z12,"เกินกำหนด","ทันกำหนด") -> ทันกำหนด
A13: 10 | G13: =$E13-$F13 -> 0 | H13: =IF($G13=0,"ครบ","ไม่ครบ") -> ครบ | J13: =VLOOKUP(I13,Sheet2!$B$1:$C$9,2,FALSE) -> #N/A | M13: =VLOOKUP(L13,Sheet2!$B$1:$C$9,2,FALSE) -> #N/A | P13: =VLOOKUP(O13,Sheet2!$B$1:$C$9,2,FALSE) -> #N/A | S13: =VLOOKUP(R13,Sheet2!$B$1:$C$9,2,FALSE) -> #N/A | U13: =$K13+$N13+$Q13+$T13 -> 0 | AD13: =IF($AA13>$Z13,"เกินกำหนด","ทันกำหนด") -> ทันกำหนด
A14: 11 | G14: =$E14-$F14 -> 0 | H14: =IF($G14=0,"ครบ","ไม่ครบ") -> ครบ | J14: =VLOOKUP(I14,Sheet2!$B$1:$C$9,2,FALSE) -> #N/A | M14: =VLOOKUP(L14,Sheet2!$B$1:$C$9,2,FALSE) -> #N/A | P14: =VLOOKUP(O14,Sheet2!$B$1:$C$9,2,FALSE) -> #N/A | S14: =VLOOKUP(R14,Sheet2!$B$1:$C$9,2,FALSE) -> #N/A | U14: =$K14+$N14+$Q14+$T14 -> 0 | AD14: =IF($AA14>$Z14,"เกินกำหนด","ทันกำหนด") -> ทันกำหนด
A15: 12 | G15: =$E15-$F15 -> 0 | H15: =IF($G15=0,"ครบ","ไม่ครบ") -> ครบ | J15: =VLOOKUP(I15,Sheet2!$B$1:$C$9,2,FALSE) -> #N/A | M15: =VLOOKUP(L15,Sheet2!$B$1:$C$9,2,FALSE) -> #N/A | P15: =VLOOKUP(O15,Sheet2!$B$1:$C$9,2,FALSE) -> #N/A | S15: =VLOOKUP(R15,Sheet2!$B$1:$C$9,2,FALSE) -> #N/A | U15: =$K15+$N15+$Q15+$T15 -> 0 | AD15: =IF($AA15>$Z15,"เกินกำหนด","ทันกำหนด") -> ทันกำหนด
... A603: 600 | G603: =$E603-$F603 -> 0 | H603: =IF($G603=0,"ครบ","ไม่ครบ") -> ครบ | J603: =VLOOKUP(I603,Sheet2!$B$1:$C$9,2,FALSE) -> #N/A | M603: =VLOOKUP(L603,Sheet2!$B$1:$C$9,2,FALSE) -> #N/A | P603: =VLOOKUP(O603,Sheet2!$B$1:$C$9,2,FALSE) -> #N/A | S603: =VLOOKUP(R603,Sheet2!$B$1:$C$9,2,FALSE) -> #N/A | U603: =$K603+$N603+$Q603+$T603 -> 0 | AD603: =IF($AA603>$Z603,"เกินกำหนด","ทันกำหนด") -> ทันกำหนด
C604: =SUBTOTAL(103,C4:C603) -> 0 | E604: =SUBTOTAL(9,E4:E603) -> 0 | AD604: =COUNTIF($AD$4:$AD603,"เกินกำหนด") -> 0 | AE604: =SUM(AE4:AE603) -> 0 | AF604: =SUM(AF4:AF603) -> 0 | AG604: =SUM(AG4:AG603) -> 0
C606: จำนวนแบบทั้งหมด (DWG) | D606: =C604 -> 0
C607: จำนวนชิ้นงานทั้งหมด (ชิ้น) | D607: =E604 -> 0
C608: จำนวนงานที่ส่งเกินกำหนด (DWG) | D608: =AD604 -> 0
C609: จำนวนงานที่ส่งตามกำหนด (DWG) | D609: =$D606-$D608 -> 0
C610: จำนวนงานที่ผิดพลาด (DWG) | D610: =AE604 -> 0
C611: KPI ส่งมอบ มากกว่า 90 % | D611: =($D609/$D606)*100 -> #DIV/0! | E611: =IF(D611>=90,"ผ่าน","ไม่ผ่าน") -> #DIV/0!
C612: KPI งานผิดพลาด น้อยกว่า 5 % | D612: =($D610/$D607)*100 -> #DIV/0! | E612: =IF(D612<=5,"ผ่าน","ไม่ผ่าน") -> #DIV/0!
C616: =SUBTOTAL(103,C4:C603) -> 0 | E616: =SUBTOTAL(9,E4:E603) -> 0
D618: \

Sheet JAN
A1: Status On Plan Work Shop
A2: ลำดับ | B2: วันที่ | C2: JOB | D2: DWG.Name | E2: จำนวนชิ้น | F2: เสร็จแล้ว | G2: ยังไม่เสร็จ | H2: สถานะ | I2: PROCESS | J2: ผู้รับผิดชอบ | K2: เวลา/ช.ม/นาที | L2: PROCESS | M2: ผู้รับผิดชอบ | N2: เวลา/ช.ม/นาที | O2: PROCESS | P2: ผู้รับผิดชอบ | Q2: เวลา/ช.ม/นาที | R2: PROCESS | S2: ผู้รับผิดชอบ | T2: เวลา/ช.ม/นาที | U2: เวลารวม | V2: OUTSOURCE | Y2: ผู้ส่งแบบ | Z2: กำหนดส่ง | AA2: วันเสร็จจริง | AB2: ผู้รับ | AC2: วันที่รับ | AD2: KPI ส่งมอบ | AE2: แก้ไข(ชิ้น) | AG2: ราคาแมท ขึ้นใหม่ | AH2: Remark
A3: ลำดับ | B3: วันที่ | C3: JOB | D3: DWG.Name | E3: จำนวนชิ้น | F3: เสร็จแล้ว | G3: ยังไม่เสร็จ | H3: สถานะ | I3: PROCESS | J3: ผู้รับผิดชอบ | K3: เวลา/ช.ม/นาที | L3: PROCESS | M3: ผู้รับผิดชอบ | N3: เวลา/ช.ม/นาที | O3: PROCESS | P3: ผู้รับผิดชอบ | Q3: เวลา/ช.ม/นาที | R3: PROCESS | S3: ผู้รับผิดชอบ | T3: เวลา/ช.ม/นาที | U3: เวลารวม | V3: Process | W3: Process | X3: Coating /Heat Treatment | Y3: ผู้ส่งแบบ | Z3: กำหนดส่ง | AA3: วันเสร็จจริง | AB3: ผู้รับ | AC3: วันที่รับ | AE3: แก้ไขได้ | AF3: ขึ้นใหม่
A4: 1 | B4: 46027 | C4: JA-2679-001-01 | D4: FIXTURE MODEL M2070-019 | E4: 20 | F4: 20 | G4: =$E4-$F4 -> 0 | H4: =IF($G4=0,"ครบ","ไม่ครบ") -> ครบ | I4: LATHE 1 | J4: =VLOOKUP(I4,Sheet2!$B$1:$C$9,2,FALSE) -> ชาญชัย | K4: 0.083333333 | M4: =VLOOKUP(L4,Sheet2!$B$1:$C$9,2,FALSE) -> #N/A | P4: =VLOOKUP(O4,Sheet2!$B$1:$C$9,2,FALSE) -> #N/A | S4: =VLOOKUP(R4,Sheet2!$B$1:$C$9,2,FALSE) -> #N/A | U4: =$K4+$N4+$Q4+$T4 -> 0.083333333 | Y4: คุณปฐมพงษ์ | Z4: 46036 | AA4: 46029 | AB4: คุณปฐมพงษ์ | AC4: 46034 | AD4: =IF($AA4>$Z4,"เกินกำหนด","ทันกำหนด") -> ทันกำหนด
A5: 2 | B5: 46027 | C5: JE-0679-020-01_Modify | D5: Cover Structure A 679-06 | E5: 2 | F5: 2 | G5: =$E5-$F5 -> 0 | H5: =IF($G5=0,"ครบ","ไม่ครบ") -> ครบ | I5: SPAR | J5: =VLOOKUP(I5,Sheet2!$B$1:$C$9,2,FALSE) -> ธนาพล | K5: 0.020833333 | M5: =VLOOKUP(L5,Sheet2!$B$1:$C$9,2,FALSE) -> #N/A | P5: =VLOOKUP(O5,Sheet2!$B$1:$C$9,2,FALSE) -> #N/A | S5: =VLOOKUP(R5,Sheet2!$B$1:$C$9,2,FALSE) -> #N/A | U5: =$K5+$N5+$Q5+$T5 -> 0.020833333 | Y5: คุณสิทธิโชค | Z5: 46030 | AA5: 46027 | AB5: คุณสิทธิโชค | AC5: 46028 | AD5: =IF($AA5>$Z5,"เกินกำหนด","ทันกำหนด") -> ทันกำหนด
A6: 3 | B6: 46027 | C6: JE-0679-020-02 | D6: Pick and Place Tray 679-15 | E6: 1 | F6: 1 | G6: =$E6-$F6 -> 0 | H6: =IF($G6=0,"ครบ","ไม่ครบ") -> ครบ | I6: CAM 2 | J6: =VLOOKUP(I6,Sheet2!$B$1:$C$9,2,FALSE) -> สุขสันต์ | K6: 0.034722222 | L6: CNC 2 | M6: รังสรรค์ | N6: 0.083333333 | O6: ML 2 | P6: =VLOOKUP(O6,Sheet2!$B$1:$C$9,2,FALSE) -> จักรกฤษณ์ | Q6: 0.041666667 | S6: =VLOOKUP(R6,Sheet2!$B$1:$C$9,2,FALSE) -> #N/A | U6: =$K6+$N6+$Q6+$T6 -> 0.15972222 | Y6: คุณสิทธิโชค | Z6: 46044 | AA6: 46041 | AB6: คุณสิทธิโชค | AC6: 46072 | AD6: =IF($AA6>$Z6,"เกินกำหนด","ทันกำหนด") -> ทันกำหนด
A7: 4 | B7: 46027 | C7: JE-0679-020-03 | D7: Pick and Place Tray 679-16 | E7: 1 | F7: 1 | G7: =$E7-$F7 -> 0 | H7: =IF($G7=0,"ครบ","ไม่ครบ") -> ครบ | I7: CAM 2 | J7: =VLOOKUP(I7,Sheet2!$B$1:$C$9,2,FALSE) -> สุขสันต์ | K7: 0.013888889 | L7: CNC 2 | M7: รังสรรค์ | N7: 0.083333333 | P7: =VLOOKUP(O7,Sheet2!$B$1:$C$9,2,FALSE) -> #N/A | S7: =VLOOKUP(R7,Sheet2!$B$1:$C$9,2,FALSE) -> #N/A | U7: =$K7+$N7+$Q7+$T7 -> 0.097222222 | Y7: คุณสิทธิโชค | Z7: 46044 | AA7: 46035 | AB7: คุณสิทธิโชค | AC7: 46072 | AD7: =IF($AA7>$Z7,"เกินกำหนด","ทันกำหนด") -> ทันกำหนด
A8: 5 | B8: 46027 | C8: JE-0679-020-04 | D8: Pick and Place Tray 679-17 | E8: 1 | F8: 1 | G8: =$E8-$F8 -> 0 | H8: =IF($G8=0,"ครบ","ไม่ครบ") -> ครบ | I8: CAM 2 | J8: =VLOOKUP(I8,Sheet2!$B$1:$C$9,2,FALSE) -> สุขสันต์ | K8: 0.020833333 | L8: CNC 3 | M8: รังสรรค์ | N8: 0.083333333 | P8: =VLOOKUP(O8,Sheet2!$B$1:$C$9,2,FALSE) -> #N/A | S8: =VLOOKUP(R8,Sheet2!$B$1:$C$9,2,FALSE) -> #N/A | U8: =$K8+$N8+$Q8+$T8 -> 0.10416667 | Y8: คุณสิทธิโชค | Z8: 46044 | AA8: 46041 | AB8: คุณสิทธิโชค | AC8: 46072 | AD8: =IF($AA8>$Z8,"เกินกำหนด","ทันกำหนด") -> ทันกำหนด
A9: 6 | B9: 46027 | C9: JE-0679-020-05 | D9: Pick and Place Tray 679-18 | E9: 2 | F9: 2 | G9: =$E9-$F9 -> 0 | H9: =IF($G9=0,"ครบ","ไม่ครบ") -> ครบ | I9: CAM 2 | J9: =VLOOKUP(I9,Sheet2!$B$1:$C$9,2,FALSE) -> สุขสันต์ | K9: 0.034722222 | L9: CNC 3 | M9: รังสรรค์ | N9: 0.083333333 | O9: ML 2 | P9: =VLOOKUP(O9,Sheet2!$B$1:$C$9,2,FALSE) -> จักรกฤษณ์ | Q9: 0.013888889 | S9: =VLOOKUP(R9,Sheet2!$B$1:$C$9,2,FALSE) -> #N/A | U9: =$K9+$N9+$Q9+$T9 -> 0.13194444 | Y9: คุณสิทธิโชค | Z9: 46044 | AA9: 46042 | AB9: คุณสิทธิโชค | AC9: 46072 | AD9: =IF($AA9>$Z9,"เกินกำหนด","ทันกำหนด") -> ทันกำหนด
A10: 7 | B10: 46027 | C10: JB-0369-006-01 | D10: ME-B0369-01-052-0039 | E10: 2 | F10: 2 | G10: =$E10-$F10 -> 0 | H10: =IF($G10=0,"ครบ","ไม่ครบ") -> ครบ | I10: LATHE 1 | J10: =VLOOKUP(I10,Sheet2!$B$1:$C$9,2,FALSE) -> ชาญชัย | K10: 0.027777778 | L10: ML 2 | M10: =VLOOKUP(L10,Sheet2!$B$1:$C$9,2,FALSE) -> จักรกฤษณ์ | N10: 0.041666667 | P10: =VLOOKUP(O10,Sheet2!$B$1:$C$9,2,FALSE) -> #N/A | S10: =VLOOKUP(R10,Sheet2!$B$1:$C$9,2,FALSE) -> #N/A | U10: =$K10+$N10+$Q10+$T10 -> 0.069444444 | Y10: คุณณัฐนนท์ | Z10: 46041 | AA10: 46034 | AB10: ส่ง BU 2 | AC10: 46038 | AD10: =IF($AA10>$Z10,"เกินกำหนด","ทันกำหนด") -> ทันกำหนด
A11: 8 | B11: 46028 | C11: JE-0702-002-01_Modify | D11: BLADE HOLDER-MIRROR - MODIFY | E11: 1 | F11: 1 | G11: =$E11-$F11 -> 0 | H11: =IF($G11=0,"ครบ","ไม่ครบ") -> ครบ | I11: CAM 2 | J11: =VLOOKUP(I11,Sheet2!$B$1:$C$9,2,FALSE) -> สุขสันต์ | K11: 0.013888889 | L11: CNC 5 | M11: สุขสันต์ | N11: 0.055555556 | P11: =VLOOKUP(O11,Sheet2!$B$1:$C$9,2,FALSE) -> #N/A | S11: =VLOOKUP(R11,Sheet2!$B$1:$C$9,2,FALSE) -> #N/A | U11: =$K11+$N11+$Q11+$T11 -> 0.069444444 | Y11: คุณพงศ์ศิริ | Z11: 46029 | AA11: 46028 | AB11: คุณมานิตย์ | AC11: 46028 | AD11: =IF($AA11>$Z11,"เกินกำหนด","ทันกำหนด") -> ทันกำหนด
A12: 9 | B12: 46028 | C12: JE-0702-002-02_Modify | D12: FLANK PLATE HY - 2 FAC4 - modify | E12: 1 | F12: 1 | G12: =$E12-$F12 -> 0 | H12: =IF($G12=0,"ครบ","ไม่ครบ") -> ครบ | I12: ML 2 | J12: =VLOOKUP(I12,Sheet2!$B$1:$C$9,2,FALSE) -> จักรกฤษณ์ | K12: 0.041666667 | M12: =VLOOKUP(L12,Sheet2!$B$1:$C$9,2,FALSE) -> #N/A | P12: =VLOOKUP(O12,Sheet2!$B$1:$C$9,2,FALSE) -> #N/A | S12: =VLOOKUP(R12,Sheet2!$B$1:$C$9,2,FALSE) -> #N/A | U12: =$K12+$N12+$Q12+$T12 -> 0.041666667 | Y12: คุณพงศ์ศิริ | Z12: 46029 | AA12: 46028 | AB12: คุณมานิตย์ | AC12: 46029 | AD12: =IF($AA12>$Z12,"เกินกำหนด","ทันกำหนด") -> ทันกำหนด
A13: 10 | B13: 46028 | C13: JA-2679-001-02 | D13: FIXTURE MODEL M2070-026 | E13: 1 | F13: 1 | G13: =$E13-$F13 -> 0 | H13: =IF($G13=0,"ครบ","ไม่ครบ") -> ครบ | I13: SPAR | J13: =VLOOKUP(I13,Sheet2!$B$1:$C$9,2,FALSE) -> ธนาพล | K13: 0.041666667 | M13: =VLOOKUP(L13,Sheet2!$B$1:$C$9,2,FALSE) -> #N/A | P13: =VLOOKUP(O13,Sheet2!$B$1:$C$9,2,FALSE) -> #N/A | S13: =VLOOKUP(R13,Sheet2!$B$1:$C$9,2,FALSE) -> #N/A | U13: =$K13+$N13+$Q13+$T13 -> 0.041666667 | Y13: คุณปฐมพงษ์ | Z13: 46029 | AA13: 46028 | AB13: คุณปฐมพงษ์ | AC13: 46029 | AD13: =IF($AA13>$Z13,"เกินกำหนด","ทันกำหนด") -> ทันกำหนด
A14: 11 | B14: 46029 | C14: JA-2660-003-01 | D14: FIXTURE MODEL M2070-010-1 | E14: 3 | F14: 3 | G14: =$E14-$F14 -> 0 | H14: =IF($G14=0,"ครบ","ไม่ครบ") -> ครบ | I14: CAM 2 | J14: =VLOOKUP(I14,Sheet2!$B$1:$C$9,2,FALSE) -> สุขสันต์ | K14: 0.052083333 | L14: CNC 4 | M14: ชนาธิศ | N14: 0.25 | P14: =VLOOKUP(O14,Sheet2!$B$1:$C$9,2,FALSE) -> #N/A | S14: =VLOOKUP(R14,Sheet2!$B$1:$C$9,2,FALSE) -> #N/A | U14: =$K14+$N14+$Q14+$T14 -> 0.30208333 | Y14: คุณปฐมพงษ์ | Z14: 46031 | AA14: 46029 | AB14: คุณปฐมพงษ์ | AC14: 46030 | AD14: =IF($AA14>$Z14,"เกินกำหนด","ทันกำหนด") -> ทันกำหนด
A15: 12 | B15: 46029 | C15: JB-0369-006-02_Modify | D15: ME-B0369-01-052-0008 | E15: 4 | F15: 4 | G15: =$E15-$F15 -> 0 | H15: =IF($G15=0,"ครบ","ไม่ครบ") -> ครบ | I15: LATHE 1 | J15: =VLOOKUP(I15,Sheet2!$B$1:$C$9,2,FALSE) -> ชาญชัย | K15: 0.020833333 | M15: =VLOOKUP(L15,Sheet2!$B$1:$C$9,2,FALSE) -> #N/A | P15: =VLOOKUP(O15,Sheet2!$B$1:$C$9,2,FALSE) -> #N/A | S15: =VLOOKUP(R15,Sheet2!$B$1:$C$9,2,FALSE) -> #N/A | U15: =$K15+$N15+$Q15+$T15 -> 0.020833333 | Y15: คุณณัฐนนท์ | Z15: 46030 | AA15: 46029 | AB15: คุณภาณุวัฒน์ | AC15: 46030 | AD15: =IF($AA15>$Z15,"เกินกำหนด","ทันกำหนด") -> ทันกำหนด
A16: 13 | B16: 46029 | C16: JA-2683-001-01 | D16: IPU KIT FOR M2014-001 | E16: 1 | F16: 1 | G16: =$E16-$F16 -> 0 | H16: =IF($G16=0,"ครบ","ไม่ครบ") -> ครบ | I16: SPAR | J16: =VLOOKUP(I16,Sheet2!$B$1:$C$9,2,FALSE) -> ธนาพล | K16: 0.048611111 | L16: CAM 1 | M16: =VLOOKUP(L16,Sheet2!$B$1:$C$9,2,FALSE) -> เพลินชัย | N16: 0.034722222 | O16: CNC 2 | P16: เพลินชัย | Q16: 0.125 | S16: =VLOOKUP(R16,Sheet2!$B$1:$C$9,2,FALSE) -> #N/A | U16: =$K16+$N16+$Q16+$T16 -> 0.20833333 | Y16: คุณปฐมพงษ์ | Z16: 46052 | AA16: 46049 | AB16: คุณปฐมพงษ์ | AC16: 46052 | AD16: =IF($AA16>$Z16,"เกินกำหนด","ทันกำหนด") -> ทันกำหนด
A17: 14 | B17: 46029 | C17: JA-2683-001-02 | D17: IPU KIT FOR M2014-002 | E17: 1 | F17: 1 | G17: =$E17-$F17 -> 0 | H17: =IF($G17=0,"ครบ","ไม่ครบ") -> ครบ | I17: SPAR | J17: =VLOOKUP(I17,Sheet2!$B$1:$C$9,2,FALSE) -> ธนาพล | K17: 0.027777778 | L17: CAM 1 | M17: =VLOOKUP(L17,Sheet2!$B$1:$C$9,2,FALSE) -> เพลินชัย | N17: 0.020833333 | O17: CNC 3 | P17: รังสรรค์ | Q17: 0.083333333 | S17: =VLOOKUP(R17,Sheet2!$B$1:$C$9,2,FALSE) -> #N/A | U17: =$K17+$N17+$Q17+$T17 -> 0.13194444 | Y17: คุณปฐมพงษ์ | Z17: 46052 | AA17: 46045 | AB17: คุณปฐมพงษ์ | AC17: 46052 | AD17: =IF($AA17>$Z17,"เกินกำหนด","ทันกำหนด") -> ทันกำหนด
A18: 15 | B18: 46029 | C18: JA-2683-001-03 | D18: IPU KIT FOR M2014-003 | E18: 1 | F18: 1 | G18: =$E18-$F18 -> 0 | H18: =IF($G18=0,"ครบ","ไม่ครบ") -> ครบ | I18: SPAR | J18: =VLOOKUP(I18,Sheet2!$B$1:$C$9,2,FALSE) -> ธนาพล | K18: 0.027777778 | L18: CAM 1 | M18: =VLOOKUP(L18,Sheet2!$B$1:$C$9,2,FALSE) -> เพลินชัย | N18: 0.020833333 | O18: CNC 3 | P18: รังสรรค์ | Q18: 0.083333333 | S18: =VLOOKUP(R18,Sheet2!$B$1:$C$9,2,FALSE) -> #N/A | U18: =$K18+$N18+$Q18+$T18 -> 0.13194444 | Y18: คุณปฐมพงษ์ | Z18: 46052 | AA18: 46044 | AB18: คุณปฐมพงษ์ | AC18: 46052 | AD18: =IF($AA18>$Z18,"เกินกำหนด","ทันกำหนด") -> ทันกำหนด
A19: 16 | B19: 46029 | C19: JA-2683-001-04 | D19: IPU KIT FOR M2014-004 | E19: 1 | F19: 1 | G19: =$E19-$F19 -> 0 | H19: =IF($G19=0,"ครบ","ไม่ครบ") -> ครบ | I19: SPAR | J19: =VLOOKUP(I19,Sheet2!$B$1:$C$9,2,FALSE) -> ธนาพล | K19: 0.010416667 | L19: ML 1 | M19: =VLOOKUP(L19,Sheet2!$B$1:$C$9,2,FALSE) -> วินัย | N19: 0.024305556 | O19: ML 3 | P19: =VLOOKUP(O19,Sheet2!$B$1:$C$9,2,FALSE) -> สรายุทธ | Q19: 0.024305556 | S19: =VLOOKUP(R19,Sheet2!$B$1:$C$9,2,FALSE) -> #N/A | U19: =$K19+$N19+$Q19+$T19 -> 0.059027778 | Y19: คุณปฐมพงษ์ | Z19: 46052 | AA19: 46042 | AB19: คุณปฐมพงษ์ | AC19: 46052 | AD19: =IF($AA19>$Z19,"เกินกำหนด","ทันกำหนด") -> ทันกำหนด
A20: 17 | B20: 46029 | C20: JA-2683-001-05 | D20: IPU KIT FOR M2014-005 | E20: 1 | F20: 1 | G20: =$E20-$F20 -> 0 | H20: =IF($G20=0,"ครบ","ไม่ครบ") -> ครบ | I20: CAM 2 | J20: =VLOOKUP(I20,Sheet2!$B$1:$C$9,2,FALSE) -> สุขสันต์ | K20: 0.020833333 | L20: CNC 4 | M20: ชนาธิศ | N20: 0.013888889 | P20: =VLOOKUP(O20,Sheet2!$B$1:$C$9,2,FALSE) -> #N/A | S20: =VLOOKUP(R20,Sheet2!$B$1:$C$9,2,FALSE) -> #N/A | U20: =$K20+$N20+$Q20+$T20 -> 0.034722222 | Y20: คุณปฐมพงษ์ | Z20: 46052 | AA20: 46050 | AB20: คุณปฐมพงษ์ | AC20: 46052 | AD20: =IF($AA20>$Z20,"เกินกำหนด","ทันกำหนด") -> ทันกำหนด
A21: 18 | B21: 46029 | C21: JA-2683-001-06 | D21: IPU KIT FOR M2014-006 | E21: 2 | F21: 2 | G21: =$E21-$F21 -> 0 | H21: =IF($G21=0,"ครบ","ไม่ครบ") -> ครบ | I21: LATHE 1 | J21: =VLOOKUP(I21,Sheet2!$B$1:$C$9,2,FALSE) -> ชาญชัย | K21: 0.020833333 | L21: ML 2 | M21: =VLOOKUP(L21,Sheet2!$B$1:$C$9,2,FALSE) -> จักรกฤษณ์ | N21: 0.013888889 | P21: =VLOOKUP(O21,Sheet2!$B$1:$C$9,2,FALSE) -> #N/A | S21: =VLOOKUP(R21,Sheet2!$B$1:$C$9,2,FALSE) -> #N/A | U21: =$K21+$N21+$Q21+$T21 -> 0.034722222 | Y21: คุณปฐมพงษ์ | Z21: 46052 | AA21: 46036 | AB21: คุณปฐมพงษ์ | AC21: 46052 | AD21: =IF($AA21>$Z21,"เกินกำหนด","ทันกำหนด") -> ทันกำหนด
A22: 19 | B22: 46029 | C22: JA-2683-001-07 | D22: IPU KIT FOR M2014-007 | E22: 1 | F22: 1 | G22: =$E22-$F22 -> 0 | H22: =IF($G22=0,"ครบ","ไม่ครบ") -> ครบ | I22: ML 1 | J22: =VLOOKUP(I22,Sheet2!$B$1:$C$9,2,FALSE) -> วินัย | K22: 0.017361111 | L22: ML 3 | M22: =VLOOKUP(L22,Sheet2!$B$1:$C$9,2,FALSE) -> สรายุทธ | N22: 0.027777778 | P22: =VLOOKUP(O22,Sheet2!$B$1:$C$9,2,FALSE) -> #N/A | S22: =VLOOKUP(R22,Sheet2!$B$1:$C$9,2,FALSE) -> #N/A | U22: =$K22+$N22+$Q22+$T22 -> 0.045138889 | Y22: คุณปฐมพงษ์ | Z22: 46052 | AA22: 46043 | AB22: คุณปฐมพงษ์ | AC22: 46052 | AD22: =IF($AA22>$Z22,"เกินกำหนด","ทันกำหนด") -> ทันกำหนด
A23: 20 | B23: 46029 | C23: JA-2683-001-08 | D23: IPU KIT FOR M2014-008 | E23: 2 | F23: 2 | G23: =$E23-$F23 -> 0 | H23: =IF($G23=0,"ครบ","ไม่ครบ") -> ครบ | I23: LATHE 1 | J23: =VLOOKUP(I23,Sheet2!$B$1:$C$9,2,FALSE) -> ชาญชัย | K23: 0.020833333 | M23: =VLOOKUP(L23,Sheet2!$B$1:$C$9,2,FALSE) -> #N/A | P23: =VLOOKUP(O23,Sheet2!$B$1:$C$9,2,FALSE) -> #N/A | S23: =VLOOKUP(R23,Sheet2!$B$1:$C$9,2,FALSE) -> #N/A | U23: =$K23+$N23+$Q23+$T23 -> 0.020833333 | Y23: คุณปฐมพงษ์ | Z23: 46052 | AA23: 46031 | AB23: คุณปฐมพงษ์ | AC23: 46052 | AD23: =IF($AA23>$Z23,"เกินกำหนด","ทันกำหนด") -> ทันกำหนด
A24: 21 | B24: 46029 | C24: JA-2683-001-09 | D24: IPU KIT FOR M2014-010 | E24: 1 | F24: 1 | G24: =$E24-$F24 -> 0 | H24: =IF($G24=0,"ครบ","ไม่ครบ") -> ครบ | I24: CAM 2 | J24: =VLOOKUP(I24,Sheet2!$B$1:$C$9,2,FALSE) -> สุขสันต์ | K24: 0.020833333 | L24: CNC 4 | M24: ชนาธิศ | N24: 0.027777778 | P24: =VLOOKUP(O24,Sheet2!$B$1:$C$9,2,FALSE) -> #N/A | S24: =VLOOKUP(R24,Sheet2!$B$1:$C$9,2,FALSE) -> #N/A | U24: =$K24+$N24+$Q24+$T24 -> 0.048611111 | Y24: คุณปฐมพงษ์ | Z24: 46052 | AA24: 46037 | AB24: คุณปฐมพงษ์ | AC24: 46052 | AD24: =IF($AA24>$Z24,"เกินกำหนด","ทันกำหนด") -> ทันกำหนด
A25: 22 | B25: 46029 | C25: JA-2683-001-10 | D25: IPU KIT FOR M2014-011 | E25: 1 | F25: 1 | G25: =$E25-$F25 -> 0 | H25: =IF($G25=0,"ครบ","ไม่ครบ") -> ครบ | I25: CAM 2 | J25: =VLOOKUP(I25,Sheet2!$B$1:$C$9,2,FALSE) -> สุขสันต์ | K25: 0.020833333 | L25: CNC 4 | M25: ชนาธิศ | N25: 0.020833333 | P25: =VLOOKUP(O25,Sheet2!$B$1:$C$9,2,FALSE) -> #N/A | S25: =VLOOKUP(R25,Sheet2!$B$1:$C$9,2,FALSE) -> #N/A | U25: =$K25+$N25+$Q25+$T25 -> 0.041666667 | Y25: คุณปฐมพงษ์ | Z25: 46052 | AA25: 46037 | AB25: คุณปฐมพงษ์ | AC25: 46052 | AD25: =IF($AA25>$Z25,"เกินกำหนด","ทันกำหนด") -> ทันกำหนด
A26: 23 | B26: 46029 | C26: JA-2683-001-11 | D26: IPU KIT FOR M2014-012 | E26: 1 | F26: 1 | G26: =$E26-$F26 -> 0 | H26: =IF($G26=0,"ครบ","ไม่ครบ") -> ครบ | I26: CAM 2 | J26: =VLOOKUP(I26,Sheet2!$B$1:$C$9,2,FALSE) -> สุขสันต์ | K26: 0.020833333 | L26: CNC 4 | M26: สุขสันต์ | N26: 0.069444444 | P26: =VLOOKUP(O26,Sheet2!$B$1:$C$9,2,FALSE) -> #N/A | S26: =VLOOKUP(R26,Sheet2!$B$1:$C$9,2,FALSE) -> #N/A | U26: =$K26+$N26+$Q26+$T26 -> 0.090277778 | Y26: คุณปฐมพงษ์ | Z26: 46052 | AA26: 46036 | AB26: คุณปฐมพงษ์ | AC26: 46052 | AD26: =IF($AA26>$Z26,"เกินกำหนด","ทันกำหนด") -> ทันกำหนด
A27: 24 | B27: 46029 | C27: JA-2683-001-12 | D27: IPU KIT FOR M2014-013 | E27: 4 | F27: 4 | G27: =$E27-$F27 -> 0 | H27: =IF($G27=0,"ครบ","ไม่ครบ") -> ครบ | I27: SPAR | J27: =VLOOKUP(I27,Sheet2!$B$1:$C$9,2,FALSE) -> ธนาพล | K27: 0.020833333 | L27: ML 1 | M27: =VLOOKUP(L27,Sheet2!$B$1:$C$9,2,FALSE) -> วินัย | N27: 0.097222222 | O27: ML 3 | P27: =VLOOKUP(O27,Sheet2!$B$1:$C$9,2,FALSE) -> สรายุทธ | Q27: 0.013888889 | S27: =VLOOKUP(R27,Sheet2!$B$1:$C$9,2,FALSE) -> #N/A | U27: =$K27+$N27+$Q27+$T27 -> 0.13194444 | Y27: คุณปฐมพงษ์ | Z27: 46052 | AA27: 46042 | AB27: คุณปฐมพงษ์ | AC27: 46052 | AD27: =IF($AA27>$Z27,"เกินกำหนด","ทันกำหนด") -> ทันกำหนด
A28: 25 | B28: 46029 | C28: JA-2683-001-13 | D28: IPU KIT FOR M2014-014 | E28: 1 | F28: 1 | G28: =$E28-$F28 -> 0 | H28: =IF($G28=0,"ครบ","ไม่ครบ") -> ครบ | I28: CAM 2 | J28: =VLOOKUP(I28,Sheet2!$B$1:$C$9,2,FALSE) -> สุขสันต์ | K28: 0.010416667 | L28: CNC 4 | M28: ชนาธิศ | N28: 0.034722222 | P28: =VLOOKUP(O28,Sheet2!$B$1:$C$9,2,FALSE) -> #N/A | S28: =VLOOKUP(R28,Sheet2!$B$1:$C$9,2,FALSE) -> #N/A | U28: =$K28+$N28+$Q28+$T28 -> 0.045138889 | Y28: คุณปฐมพงษ์ | Z28: 46052 | AA28: 46036 | AB28: คุณปฐมพงษ์ | AC28: 46052 | AD28: =IF($AA28>$Z28,"เกินกำหนด","ทันกำหนด") -> ทันกำหนด
A29: 26 | B29: 46029 | C29: JA-2683-001-14 | D29: IPU KIT FOR M2014-015 | E29: 2 | F29: 2 | G29: =$E29-$F29 -> 0 | H29: =IF($G29=0,"ครบ","ไม่ครบ") -> ครบ | I29: CAM 2 | J29: =VLOOKUP(I29,Sheet2!$B$1:$C$9,2,FALSE) -> สุขสันต์ | K29: 0.010416667 | L29: CNC 4 | M29: สุขสันต์ | N29: 0.020833333 | P29: =VLOOKUP(O29,Sheet2!$B$1:$C$9,2,FALSE) -> #N/A | S29: =VLOOKUP(R29,Sheet2!$B$1:$C$9,2,FALSE) -> #N/A | U29: =$K29+$N29+$Q29+$T29 -> 0.03125 | Y29: คุณปฐมพงษ์ | Z29: 46052 | AA29: 46036 | AB29: คุณปฐมพงษ์ | AC29: 46052 | AD29: =IF($AA29>$Z29,"เกินกำหนด","ทันกำหนด") -> ทันกำหนด
A30: 27 | B30: 46029 | C30: JA-2683-001-15 | D30: IPU KIT FOR M2014-017 | E30: 1 | F30: 1 | G30: =$E30-$F30 -> 0 | H30: =IF($G30=0,"ครบ","ไม่ครบ") -> ครบ | I30: SPAR | J30: =VLOOKUP(I30,Sheet2!$B$1:$C$9,2,FALSE) -> ธนาพล | K30: 0.010416667 | L30: ML 1 | M30: =VLOOKUP(L30,Sheet2!$B$1:$C$9,2,FALSE) -> วินัย | N30: 0.0625 | O30: CAM 2 | P30: =VLOOKUP(O30,Sheet2!$B$1:$C$9,2,FALSE) -> สุขสันต์ | Q30: 0.0069444444 | R30: CNC 4 | S30: ชนาธิศ | T30: 0.010416667 | U30: =$K30+$N30+$Q30+$T30 -> 0.090277778 | Y30: คุณปฐมพงษ์ | Z30: 46052 | AA30: 46044 | AB30: คุณปฐมพงษ์ | AC30: 46052 | AD30: =IF($AA30>$Z30,"เกินกำหนด","ทันกำหนด") -> ทันกำหนด
A31: 28 | B31: 46029 | C31: JA-2683-001-16 | D31: IPU KIT FOR M2014-018 | E31: 1 | F31: 1 | G31: =$E31-$F31 -> 0 | H31: =IF($G31=0,"ครบ","ไม่ครบ") -> ครบ | I31: CAM 2 | J31: =VLOOKUP(I31,Sheet2!$B$1:$C$9,2,FALSE) -> สุขสันต์ | K31: 0.013888889 | L31: CNC 4 | M31: สุขสันต์ | N31: 0.034722222 | P31: =VLOOKUP(O31,Sheet2!$B$1:$C$9,2,FALSE) -> #N/A | S31: =VLOOKUP(R31,Sheet2!$B$1:$C$9,2,FALSE) -> #N/A | U31: =$K31+$N31+$Q31+$T31 -> 0.048611111 | Y31: คุณปฐมพงษ์ | Z31: 46052 | AA31: 46036 | AB31: คุณปฐมพงษ์ | AC31: 46052 | AD31: =IF($AA31>$Z31,"เกินกำหนด","ทันกำหนด") -> ทันกำหนด
A32: 29 | B32: 46029 | C32: JA-2683-001-17 | D32: IPU KIT FOR M2014-019 | E32: 1 | F32: 1 | G32: =$E32-$F32 -> 0 | H32: =IF($G32=0,"ครบ","ไม่ครบ") -> ครบ | I32: CAM 2 | J32: =VLOOKUP(I32,Sheet2!$B$1:$C$9,2,FALSE) -> สุขสันต์ | K32: 0.034722222 | L32: CNC 4 | M32: สุขสันต์ | N32: 0.14583333 | P32: =VLOOKUP(O32,Sheet2!$B$1:$C$9,2,FALSE) -> #N/A | S32: =VLOOKUP(R32,Sheet2!$B$1:$C$9,2,FALSE) -> #N/A | U32: =$K32+$N32+$Q32+$T32 -> 0.18055556 | Y32: คุณปฐมพงษ์ | Z32: 46052 | AA32: 46039 | AB32: คุณปฐมพงษ์ | AC32: 46052 | AD32: =IF($AA32>$Z32,"เกินกำหนด","ทันกำหนด") -> ทันกำหนด
A33: 30 | B33: 46029 | C33: JA-2683-001-18 | D33: IPU KIT FOR M2014-020 | E33: 1 | F33: 1 | G33: =$E33-$F33 -> 0 | H33: =IF($G33=0,"ครบ","ไม่ครบ") -> ครบ | I33: CAM 2 | J33: =VLOOKUP(I33,Sheet2!$B$1:$C$9,2,FALSE) -> สุขสันต์ | K33: 0.020833333 | L33: CNC 4 | M33: ชนาธิศ | N33: 0.020833333 | P33: =VLOOKUP(O33,Sheet2!$B$1:$C$9,2,FALSE) -> #N/A | S33: =VLOOKUP(R33,Sheet2!$B$1:$C$9,2,FALSE) -> #N/A | U33: =$K33+$N33+$Q33+$T33 -> 0.041666667 | Y33: คุณปฐมพงษ์ | Z33: 46052 | AA33: 46050 | AB33: คุณปฐมพงษ์ | AC33: 46052 | AD33: =IF($AA33>$Z33,"เกินกำหนด","ทันกำหนด") -> ทันกำหนด
A34: 31 | B34: 46029 | C34: JA-2683-001-19 | D34: IPU KIT FOR M2014-021 | E34: 4 | F34: 4 | G34: =$E34-$F34 -> 0 | H34: =IF($G34=0,"ครบ","ไม่ครบ") -> ครบ | I34: LATHE 1 | J34: =VLOOKUP(I34,Sheet2!$B$1:$C$9,2,FALSE) -> ชาญชัย | K34: 0.041666667 | M34: =VLOOKUP(L34,Sheet2!$B$1:$C$9,2,FALSE) -> #N/A | P34: =VLOOKUP(O34,Sheet2!$B$1:$C$9,2,FALSE) -> #N/A | S34: =VLOOKUP(R34,Sheet2!$B$1:$C$9,2,FALSE) -> #N/A | U34: =$K34+$N34+$Q34+$T34 -> 0.041666667 | Y34: คุณปฐมพงษ์ | Z34: 46052 | AA34: 46034 | AB34: คุณปฐมพงษ์ | AC34: 46052 | AD34: =IF($AA34>$Z34,"เกินกำหนด","ทันกำหนด") -> ทันกำหนด
A35: 32 | B35: 46029 | C35: JA-2683-001-20 | D35: IPU KIT FOR M2014-022 | E35: 1 | F35: 1 | G35: =$E35-$F35 -> 0 | H35: =IF($G35=0,"ครบ","ไม่ครบ") -> ครบ | I35: CAM 2 | J35: =VLOOKUP(I35,Sheet2!$B$1:$C$9,2,FALSE) -> สุขสันต์ | K35: 0.024305556 | L35: CNC 4 | M35: ชนาธิศ | N35: 0.027777778 | P35: =VLOOKUP(O35,Sheet2!$B$1:$C$9,2,FALSE) -> #N/A | S35: =VLOOKUP(R35,Sheet2!$B$1:$C$9,2,FALSE) -> #N/A | U35: =$K35+$N35+$Q35+$T35 -> 0.052083333 | Y35: คุณปฐมพงษ์ | Z35: 46052 | AA35: 46050 | AB35: คุณปฐมพงษ์ | AC35: 46052 | AD35: =IF($AA35>$Z35,"เกินกำหนด","ทันกำหนด") -> ทันกำหนด
A36: 33 | B36: 46029 | C36: JA-2683-001-21 | D36: IPU KIT FOR M2014-023 | E36: 1 | F36: 1 | G36: =$E36-$F36 -> 0 | H36: =IF($G36=0,"ครบ","ไม่ครบ") -> ครบ | I36: ML 1 | J36: =VLOOKUP(I36,Sheet2!$B$1:$C$9,2,FALSE) -> วินัย | K36: 0.013888889 | L36: ML 3 | M36: =VLOOKUP(L36,Sheet2!$B$1:$C$9,2,FALSE) -> สรายุทธ | N36: 0.0069444444 | P36: =VLOOKUP(O36,Sheet2!$B$1:$C$9,2,FALSE) -> #N/A | S36: =VLOOKUP(R36,Sheet2!$B$1:$C$9,2,FALSE) -> #N/A | U36: =$K36+$N36+$Q36+$T36 -> 0.020833333 | Y36: คุณปฐมพงษ์ | Z36: 46052 | AA36: 46036 | AB36: คุณปฐมพงษ์ | AC36: 46052 | AD36: =IF($AA36>$Z36,"เกินกำหนด","ทันกำหนด") -> ทันกำหนด
A37: 34 | B37: 46029 | C37: JA-2680-001-01 | D37: Back plate | E37: 3 | F37: 3 | G37: =$E37-$F37 -> 0 | H37: =IF($G37=0,"ครบ","ไม่ครบ") -> ครบ | I37: SPAR | J37: =VLOOKUP(I37,Sheet2!$B$1:$C$9,2,FALSE) -> ธนาพล | K37: 0.055555556 | L37: CAM 1 | M37: =VLOOKUP(L37,Sheet2!$B$1:$C$9,2,FALSE) -> เพลินชัย | N37: 0.041666667 | O37: CNC 1 | P37: รังสรรค์ | Q37: 0.35416667 | S37: =VLOOKUP(R37,Sheet2!$B$1:$C$9,2,FALSE) -> #N/A | U37: =$K37+$N37+$Q37+$T37 -> 0.45138889 | Y37: คุณปฐมพงษ์ | Z37: 46055 | AA37: 46048 | AB37: คุณปฐมพงษ์ | AC37: 46056 | AD37: =IF($AA37>$Z37,"เกินกำหนด","ทันกำหนด") -> ทันกำหนด
A38: 35 | B38: 46029 | C38: JA-2680-001-02 | D38: Bar | E38: 12 | F38: 12 | G38: =$E38-$F38 -> 0 | H38: =IF($G38=0,"ครบ","ไม่ครบ") -> ครบ | I38: SPAR | J38: =VLOOKUP(I38,Sheet2!$B$1:$C$9,2,FALSE) -> ธนาพล | K38: 0.0625 | L38: CAM 1 | M38: =VLOOKUP(L38,Sheet2!$B$1:$C$9,2,FALSE) -> เพลินชัย | N38: 0.027777778 | O38: CNC 3 | P38: รังสรรค์ | Q38: 0.29166667 | R38: ML 1 | S38: =VLOOKUP(R38,Sheet2!$B$1:$C$9,2,FALSE) -> วินัย | T38: 0.041666667 | U38: =$K38+$N38+$Q38+$T38 -> 0.42361111 | Y38: คุณปฐมพงษ์ | Z38: 46055 | AA38: 46048 | AB38: คุณปฐมพงษ์ | AC38: 46056 | AD38: =IF($AA38>$Z38,"เกินกำหนด","ทันกำหนด") -> ทันกำหนด
A39: 36 | B39: 46029 | C39: JA-2680-001-03 | D39: Base copper | E39: 3 | F39: 3 | G39: =$E39-$F39 -> 0 | H39: =IF($G39=0,"ครบ","ไม่ครบ") -> ครบ | I39: CAM 2 | J39: =VLOOKUP(I39,Sheet2!$B$1:$C$9,2,FALSE) -> สุขสันต์ | K39: 0.010416667 | L39: CNC 4 | M39: ชนาธิศ | N39: 0.125 | P39: =VLOOKUP(O39,Sheet2!$B$1:$C$9,2,FALSE) -> #N/A | S39: =VLOOKUP(R39,Sheet2!$B$1:$C$9,2,FALSE) -> #N/A | U39: =$K39+$N39+$Q39+$T39 -> 0.13541667 | Y39: คุณปฐมพงษ์ | Z39: 46055 | AA39: 46041 | AB39: คุณปฐมพงษ์ | AC39: 46056 | AD39: =IF($AA39>$Z39,"เกินกำหนด","ทันกำหนด") -> ทันกำหนด
A40: 37 | B40: 46029 | C40: JA-2680-001-04 | D40: Base LM | E40: 12 | F40: 12 | G40: =$E40-$F40 -> 0 | H40: =IF($G40=0,"ครบ","ไม่ครบ") -> ครบ | I40: CAM 1 | J40: =VLOOKUP(I40,Sheet2!$B$1:$C$9,2,FALSE) -> เพลินชัย | K40: 0.020833333 | L40: CNC 1 | M40: เพลินชัย | N40: 0.33333333 | O40: CNC 1 | P40: รังสรรค์ | Q40: 0.29166667 | S40: =VLOOKUP(R40,Sheet2!$B$1:$C$9,2,FALSE) -> #N/A | U40: =$K40+$N40+$Q40+$T40 -> 0.64583333 | Y40: คุณปฐมพงษ์ | Z40: 46055 | AA40: 46050 | AB40: คุณปฐมพงษ์ | AC40: 46056 | AD40: =IF($AA40>$Z40,"เกินกำหนด","ทันกำหนด") -> ทันกำหนด
...

Sheet D-0793
A1: No. | B1: JOB | C1: Draw. | D1: Qty. | E1: Process | F1: Outside | G1: coating | H1: Due date | I1: Priority | J1: STATUS
A2: 1 | B2: JD-0793-001-01 | C2: MATTEL-VSMC-A01 | D2: 3 | E2: CAM 1 | F2: - | G2: - | H2: 46080 | J2: รับแล้ว
A3: 2 | B3: JD-0793-001-02 | C3: MATTEL-VSMC-A02 | D3: 3 | E3: CAM 1+ML | F3: - | G3: - | H3: 46080 | J3: รับแล้ว
A4: 3 | B4: JD-0793-001-03 | C4: MATTEL-VSMC-A03 | D4: 3 | E4: CAM 1 | F4: - | G4: - | H4: 46080 | J4: รับแล้ว
A5: 4 | B5: JD-0793-001-04 | C5: MATTEL-VSMC-A04 | D5: 3 | E5: CAM 1+ML | F5: - | G5: - | H5: 46080 | J5: รับแล้ว
A6: 5 | B6: JD-0793-001-05 | C6: MATTEL-VSMC-A05 | D6: 3 | E6: CAM 2 | F6: - | G6: - | H6: 46080 | J6: รับแล้ว
A7: 6 | B7: JD-0793-001-06 | C7: MATTEL-VSMC-A06 | D7: 6 | E7: CAM 1 | F7: - | G7: - | H7: 46080 | J7: รับแล้ว
A8: 7 | B8: JD-0793-001-07 | C8: MATTEL-VSMC-A07 | D8: 3 | E8: ML 1 | F8: - | G8: - | H8: 46080 | J8: รับแล้ว
A9: 8 | B9: JD-0793-001-08 | C9: MATTEL-VSMC-A13 | D9: 3 | E9: CAM 1 | F9: - | G9: - | H9: 46084 | J9: รับแล้ว
A10: 9 | B10: JD-0793-001-09 | C10: MATTEL-VSMC-A14 | D10: 3 | E10: CAM 2 | F10: - | G10: - | H10: 46084 | J10: รับแล้ว
A11: 10 | B11: JD-0793-001-10 | C11: MATTEL-VSMC-A15 | D11: 3 | E11: LATHE 1+ML | F11: - | G11: - | H11: 46080 | J11: รับแล้ว
A12: 11 | B12: JD-0793-001-11 | C12: MATTEL-VSMC-A16 | D12: 3 | E12: LATHE 1+ML | F12: Wire cut | G12: - | H12: 46080 | J12: รับแล้ว
A13: 12 | B13: JD-0793-001-12 | C13: MATTEL-VSMC-A17 | D13: 3 | E13: LATHE 1+ML | F13: - | G13: - | H13: 46080 | J13: รับแล้ว
... A55: 54 | B55: JD-0793-001-54 | C55: MATTEL-VSMC-B14 | D55: 3 | E55: SPAR | F55: - | G55: - | H55: 46087 | J55: รับแล้ว

Sheet FEB
A1: Status On Plan Work Shop
A2: ลำดับ | B2: วันที่ | C2: JOB | D2: DWG.Name | E2: จำนวนชิ้น | F2: เสร็จแล้ว | G2: ยังไม่เสร็จ | H2: สถานะ | I2: PROCESS | J2: ผู้รับผิดชอบ | K2: เวลา/ช.ม/นาที | L2: PROCESS | M2: ผู้รับผิดชอบ | N2: เวลา/ช.ม/นาที | O2: PROCESS | P2: ผู้รับผิดชอบ | Q2: เวลา/ช.ม/นาที | R2: PROCESS | S2: ผู้รับผิดชอบ | T2: เวลา/ช.ม/นาที | U2: เวลารวม | V2: OUTSOURCE | Y2: ผู้ส่งแบบ | Z2: กำหนดส่ง | AA2: วันเสร็จจริง | AB2: ผู้รับ | AC2: วันที่รับ | AD2: KPI ส่งมอบ | AE2: แก้ไข(ชิ้น) | AG2: ราคาแมท ขึ้นใหม่ | AH2: Remark
A3: ลำดับ | B3: วันที่ | C3: JOB | D3: DWG.Name | E3: จำนวนชิ้น | F3: เสร็จแล้ว | G3: ยังไม่เสร็จ | H3: สถานะ | I3: PROCESS | J3: ผู้รับผิดชอบ | K3: เวลา/ช.ม/นาที | L3: PROCESS | M3: ผู้รับผิดชอบ | N3: เวลา/ช.ม/นาที | O3: PROCESS | P3: ผู้รับผิดชอบ | Q3: เวลา/ช.ม/นาที | R3: PROCESS | S3: ผู้รับผิดชอบ | T3: เวลา/ช.ม/นาที | U3: เวลารวม | V3: Process | W3: Process | X3: Coating /Heat Treatment | Y3: ผู้ส่งแบบ | Z3: กำหนดส่ง | AA3: วันเสร็จจริง | AB3: ผู้รับ | AC3: วันที่รับ | AE3: แก้ไขได้ | AF3: ขึ้นใหม่
A4: 1 | B4: 46055 | C4: JE-0711-002-01 | D4: Gripper Load out 711-02 | E4: 4 | F4: 4 | G4: =$E4-$F4 -> 0 | H4: =IF($G4=0,"ครบ","ไม่ครบ") -> ครบ | I4: LATHE 2 | J4: =VLOOKUP(I4,Sheet2!$B$1:$C$9,2,FALSE) -> สรายุทธ | K4: 0.125 | L4: ML 1 | M4: =VLOOKUP(L4,Sheet2!$B$1:$C$9,2,FALSE) -> วินัย | N4: 0.14236111 | P4: =VLOOKUP(O4,Sheet2!$B$1:$C$9,2,FALSE) -> #N/A | S4: =VLOOKUP(R4,Sheet2!$B$1:$C$9,2,FALSE) -> #N/A | U4: =$K4+$N4+$Q4+$T4 -> 0.26736111 | Y4: คุณสิทธิโชค | Z4: 46063 | AA4: 46058 | AB4: คุณสิทธิโชค | AC4: 46069 | AD4: =IF($AA4>$Z4,"เกินกำหนด","ทันกำหนด") -> ทันกำหนด
A5: 2 | B5: 46055 | C5: JE-0711-002-02 | D5: Gripper Load out 711-03 | E5: 4 | F5: 4 | G5: =$E5-$F5 -> 0 | H5: =IF($G5=0,"ครบ","ไม่ครบ") -> ครบ | I5: LATHE 1 | J5: =VLOOKUP(I5,Sheet2!$B$1:$C$9,2,FALSE) -> ชาญชัย | K5: 0.0625 | L5: ML 1 | M5: =VLOOKUP(L5,Sheet2!$B$1:$C$9,2,FALSE) -> วินัย | N5: 0.038194444 | P5: =VLOOKUP(O5,Sheet2!$B$1:$C$9,2,FALSE) -> #N/A | S5: =VLOOKUP(R5,Sheet2!$B$1:$C$9,2,FALSE) -> #N/A | U5: =$K5+$N5+$Q5+$T5 -> 0.10069444 | Y5: คุณสิทธิโชค | Z5: 46063 | AA5: 46056 | AB5: คุณสิทธิโชค | AC5: 46071 | AD5: =IF($AA5>$Z5,"เกินกำหนด","ทันกำหนด") -> ทันกำหนด
A6: 3 | B6: 46055 | C6: JD-0758-009-01 | D6: SIS-FBN-PTC-0C-09 | E6: 4 | F6: 4 | G6: =$E6-$F6 -> 0 | H6: =IF($G6=0,"ครบ","ไม่ครบ") -> ครบ | I6: LATHE 1 | J6: =VLOOKUP(I6,Sheet2!$B$1:$C$9,2,FALSE) -> ชาญชัย | K6: 0.041666667 | M6: =VLOOKUP(L6,Sheet2!$B$1:$C$9,2,FALSE) -> #N/A | P6: =VLOOKUP(O6,Sheet2!$B$1:$C$9,2,FALSE) -> #N/A | S6: =VLOOKUP(R6,Sheet2!$B$1:$C$9,2,FALSE) -> #N/A | U6: =$K6+$N6+$Q6+$T6 -> 0.041666667 | Y6: คุณยุทธนา | Z6: 46056 | AA6: 46055 | AB6: คุณอภิชิต | AC6: 46056 | AD6: =IF($AA6>$Z6,"เกินกำหนด","ทันกำหนด") -> ทันกำหนด
A7: 4 | B7: 46055 | C7: JA-2695-001-01 | D7: F2695-A-0025-00 | E7: 2 | F7: 2 | G7: =$E7-$F7 -> 0 | H7: =IF($G7=0,"ครบ","ไม่ครบ") -> ครบ | I7: SPAR | J7: =VLOOKUP(I7,Sheet2!$B$1:$C$9,2,FALSE) -> ธนาพล | K7: 0.048611111 | M7: =VLOOKUP(L7,Sheet2!$B$1:$C$9,2,FALSE) -> #N/A | P7: =VLOOKUP(O7,Sheet2!$B$1:$C$9,2,FALSE) -> #N/A | S7: =VLOOKUP(R7,Sheet2!$B$1:$C$9,2,FALSE) -> #N/A | U7: =$K7+$N7+$Q7+$T7 -> 0.048611111 | Y7: คุณยุทธนา | Z7: 46065 | AA7: 46056 | AB7: คุณยุทธนา | AC7: 46069 | AD7: =IF($AA7>$Z7,"เกินกำหนด","ทันกำหนด") -> ทันกำหนด
A8: 5 | B8: 46055 | C8: JA-2695-001-02 | D8: F2695-A-0028-00 | E8: 2 | F8: 2 | G8: =$E8-$F8 -> 0 | H8: =IF($G8=0,"ครบ","ไม่ครบ") -> ครบ | I8: ML 2 | J8: =VLOOKUP(I8,Sheet2!$B$1:$C$9,2,FALSE) -> จักรกฤษณ์ | K8: 0.010416667 | L8: ML 1 | M8: =VLOOKUP(L8,Sheet2!$B$1:$C$9,2,FALSE) -> วินัย | N8: 0.024305556 | P8: =VLOOKUP(O8,Sheet2!$B$1:$C$9,2,FALSE) -> #N/A | S8: =VLOOKUP(R8,Sheet2!$B$1:$C$9,2,FALSE) -> #N/A | U8: =$K8+$N8+$Q8+$T8 -> 0.034722222 | X8: รมดำ | Y8: คุณยุทธนา | Z8: 46065 | AA8: 46064 | AB8: คุณยุทธนา | AC8: 46069 | AD8: =IF($AA8>$Z8,"เกินกำหนด","ทันกำหนด") -> ทันกำหนด
A9: 6 | B9: 46055 | C9: JA-2695-001-03 | D9: F2695-A-0030-00 | E9: 1 | F9: 1 | G9: =$E9-$F9 -> 0 | H9: =IF($G9=0,"ครบ","ไม่ครบ") -> ครบ | I9: ML 2 | J9: =VLOOKUP(I9,Sheet2!$B$1:$C$9,2,FALSE) -> จักรกฤษณ์ | K9: 0.041666667 | L9: ML 1 | M9: =VLOOKUP(L9,Sheet2!$B$1:$C$9,2,FALSE) -> วินัย | N9: 0.010416667 | P9: =VLOOKUP(O9,Sheet2!$B$1:$C$9,2,FALSE) -> #N/A | S9: =VLOOKUP(R9,Sheet2!$B$1:$C$9,2,FALSE) -> #N/A | U9: =$K9+$N9+$Q9+$T9 -> 0.052083333 | Y9: คุณยุทธนา | Z9: 46065 | AA9: 46056 | AB9: คุณยุทธนา | AC9: 46069 | AD9: =IF($AA9>$Z9,"เกินกำหนด","ทันกำหนด") -> ทันกำหนด
A10: 7 | B10: 46055 | C10: JA-2695-001-04 | D10: F2695-A-0031-00 | E10: 1 | F10: 1 | G10: =$E10-$F10 -> 0 | H10: =IF($G10=0,"ครบ","ไม่ครบ") -> ครบ | I10: ML 2 | J10: =VLOOKUP(I10,Sheet2!$B$1:$C$9,2,FALSE) -> จักรกฤษณ์ | K10: 0.024305556 | L10: ML 1 | M10: =VLOOKUP(L10,Sheet2!$B$1:$C$9,2,FALSE) -> วินัย | N10: 0.017361111 | P10: =VLOOKUP(O10,Sheet2!$B$1:$C$9,2,FALSE) -> #N/A | S10: =VLOOKUP(R10,Sheet2!$B$1:$C$9,2,FALSE) -> #N/A | U10: =$K10+$N10+$Q10+$T10 -> 0.041666667 | Y10: คุณยุทธนา | Z10: 46065 | AA10: 46056 | AB10: คุณยุทธนา | AC10: 46069 | AD10: =IF($AA10>$Z10,"เกินกำหนด","ทันกำหนด") -> ทันกำหนด | AE10: 1 | AH10: เฟสความหนาผิด Spec. / จักรกฤษณ์
A11: 8 | B11: 46055 | C11: JE-0705-004-01_Modify | D11: BASE PLATE AUTO MARK DOT ECU - 007-MODIFY | E11: 1 | F11: 1 | G11: =$E11-$F11 -> 0 | H11: =IF($G11=0,"ครบ","ไม่ครบ") -> ครบ | I11: CAM 2 | J11: =VLOOKUP(I11,Sheet2!$B$1:$C$9,2,FALSE) -> สุขสันต์ | K11: 0.0069444444 | L11: CNC 5 | M11: สุขสันต์ | N11: 0.020833333 | P11: =VLOOKUP(O11,Sheet2!$B$1:$C$9,2,FALSE) -> #N/A | S11: =VLOOKUP(R11,Sheet2!$B$1:$C$9,2,FALSE) -> #N/A | U11: =$K11+$N11+$Q11+$T11 -> 0.027777778 | Y11: คุณมนัสนันท์ | Z11: 46056 | AA11: 46055 | AB11: คุณมนัสนันท์ | AC11: 46058 | AD11: =IF($AA11>$Z11,"เกินกำหนด","ทันกำหนด") -> ทันกำหนด
A12: 9 | B12: 46055 | C12: JE-0716-001-01 | D12: ANGLE SHAFT CV OUTFEED | E12: 2 | F12: 2 | G12: =$E12-$F12 -> 0 | H12: =IF($G12=0,"ครบ","ไม่ครบ") -> ครบ | I12: LATHE 1 | J12: =VLOOKUP(I12,Sheet2!$B$1:$C$9,2,FALSE) -> ชาญชัย | K12: 0.020833333 | L12: ML 2 | M12: =VLOOKUP(L12,Sheet2!$B$1:$C$9,2,FALSE) -> จักรกฤษณ์ | N12: 0.076388889 | P12: =VLOOKUP(O12,Sheet2!$B$1:$C$9,2,FALSE) -> #N/A | S12: =VLOOKUP(R12,Sheet2!$B$1:$C$9,2,FALSE) -> #N/A | U12: =$K12+$N12+$Q12+$T12 -> 0.097222222 | Y12: คุณมนัสนันท์ | Z12: 46070 | AA12: 46059 | AB12: คุณชาคริส | AC12: 46080 | AD12: =IF($AA12>$Z12,"เกินกำหนด","ทันกำหนด") -> ทันกำหนด
A13: 10 | B13: 46055 | C13: JE-0716-001-02 | D13: LINK SHAFT MOTOR BRACKET BELT CV | E13: 2 | F13: 2 | G13: =$E13-$F13 -> 0 | H13: =IF($G13=0,"ครบ","ไม่ครบ") -> ครบ | I13: LATHE 1 | J13: =VLOOKUP(I13,Sheet2!$B$1:$C$9,2,FALSE) -> ชาญชัย | K13: 0.027777778 | M13: =VLOOKUP(L13,Sheet2!$B$1:$C$9,2,FALSE) -> #N/A | P13: =VLOOKUP(O13,Sheet2!$B$1:$C$9,2,FALSE) -> #N/A | S13: =VLOOKUP(R13,Sheet2!$B$1:$C$9,2,FALSE) -> #N/A | U13: =$K13+$N13+$Q13+$T13 -> 0.027777778 | Y13: คุณมนัสนันท์ | Z13: 46070 | AA13: 46057 | AB13: คุณชาคริส | AC13: 46080 | AD13: =IF($AA13>$Z13,"เกินกำหนด","ทันกำหนด") -> ทันกำหนด
A14: 11 | B14: 46055 | C14: JE-0716-001-03 | D14: SHAFT BRUSH ROLLER CV | E14: 5 | F14: 5 | G14: =$E14-$F14 -> 0 | H14: =IF($G14=0,"ครบ","ไม่ครบ") -> ครบ | I14: LATHE 1 | J14: =VLOOKUP(I14,Sheet2!$B$1:$C$9,2,FALSE) -> ชาญชัย | K14: 0.18055556 | L14: ML 1 | M14: =VLOOKUP(L14,Sheet2!$B$1:$C$9,2,FALSE) -> วินัย | N14: 0.0625 | P14: =VLOOKUP(O14,Sheet2!$B$1:$C$9,2,FALSE) -> #N/A | S14: =VLOOKUP(R14,Sheet2!$B$1:$C$9,2,FALSE) -> #N/A | U14: =$K14+$N14+$Q14+$T14 -> 0.24305556 | Y14: คุณมนัสนันท์ | Z14: 46070 | AA14: 46062 | AB14: คุณชาคริส | AC14: 46080 | AD14: =IF($AA14>$Z14,"เกินกำหนด","ทันกำหนด") -> ทันกำหนด
A15: 12 | B15: 46055 | C15: JE-0716-001-04_Modify | D15: STUD BOLT-M16 | E15: 2 | F15: 2 | G15: =$E15-$F15 -> 0 | H15: =IF($G15=0,"ครบ","ไม่ครบ") -> ครบ | I15: LATHE 1 | J15: =VLOOKUP(I15,Sheet2!$B$1:$C$9,2,FALSE) -> ชาญชัย | K15: 0.034722222 | M15: =VLOOKUP(L15,Sheet2!$B$1:$C$9,2,FALSE) -> #N/A | P15: =VLOOKUP(O15,Sheet2!$B$1:$C$9,2,FALSE) -> #N/A | S15: =VLOOKUP(R15,Sheet2!$B$1:$C$9,2,FALSE) -> #N/A | U15: =$K15+$N15+$Q15+$T15 -> 0.034722222 | X15: ชุบซิงค์ขาว | Y15: คุณมนัสนันท์ | Z15: 46070 | AA15: 46064 | AB15: คุณชาคริส | AC15: 46080 | AD15: =IF($AA15>$Z15,"เกินกำหนด","ทันกำหนด") -> ทันกำหนด
A16: 13 | B16: 46056 | C16: JB-0376-002-01_Modify | D16: ME-B0376-01-009-0019 | E16: 8 | F16: 8 | G16: =$E16-$F16 -> 0 | H16: =IF($G16=0,"ครบ","ไม่ครบ") -> ครบ | I16: LATHE 1 | J16: =VLOOKUP(I16,Sheet2!$B$1:$C$9,2,FALSE) -> ชาญชัย | K16: 0.027777778 | M16: =VLOOKUP(L16,Sheet2!$B$1:$C$9,2,FALSE) -> #N/A | P16: =VLOOKUP(O16,Sheet2!$B$1:$C$9,2,FALSE) -> #N/A | S16: =VLOOKUP(R16,Sheet2!$B$1:$C$9,2,FALSE) -> #N/A | U16: =$K16+$N16+$Q16+$T16 -> 0.027777778 | Y16: คุณณัฐนนท์ | Z16: 46056 | AA16: 46056 | AB16: คุณวิศรุต | AC16: 46056 | AD16: =IF($AA16>$Z16,"เกินกำหนด","ทันกำหนด") -> ทันกำหนด
A17: 14 | B17: 46056 | C17: JA-2557-007_Modify | D17: Wave Pallet GXC_G78342-027 REV3 | E17: 4 | F17: 4 | G17: =$E17-$F17 -> 0 | H17: =IF($G17=0,"ครบ","ไม่ครบ") -> ครบ | I17: ML 2 | J17: =VLOOKUP(I17,Sheet2!$B$1:$C$9,2,FALSE) -> จักรกฤษณ์ | K17: 0.027777778 | M17: =VLOOKUP(L17,Sheet2!$B$1:$C$9,2,FALSE) -> #N/A | P17: =VLOOKUP(O17,Sheet2!$B$1:$C$9,2,FALSE) -> #N/A | S17: =VLOOKUP(R17,Sheet2!$B$1:$C$9,2,FALSE) -> #N/A | U17: =$K17+$N17+$Q17+$T17 -> 0.027777778 | Y17: คุณจักรกฤษณ์ | Z17: 46056 | AA17: 46056 | AB17: คุณจักรกฤษณ์ | AC17: 46056 | AD17: =IF($AA17>$Z17,"เกินกำหนด","ทันกำหนด") -> ทันกำหนด
A18: 15 | B18: 46056 | C18: JC-0147-001-01 | D18: XAAR Multi-Tester 002 | E18: 6 | F18: 6 | G18: =$E18-$F18 -> 0 | H18: =IF($G18=0,"ครบ","ไม่ครบ") -> ครบ | I18: LATHE 1 | J18: =VLOOKUP(I18,Sheet2!$B$1:$C$9,2,FALSE) -> ชาญชัย | K18: 0.041666667 | M18: =VLOOKUP(L18,Sheet2!$B$1:$C$9,2,FALSE) -> #N/A | P18: =VLOOKUP(O18,Sheet2!$B$1:$C$9,2,FALSE) -> #N/A | S18: =VLOOKUP(R18,Sheet2!$B$1:$C$9,2,FALSE) -> #N/A | U18: =$K18+$N18+$Q18+$T18 -> 0.041666667 | Y18: คุณจักรกฤษณ์ | Z18: 46065 | AA18: 46056 | AB18: คุณจักรกฤษณ์ | AC18: 46087 | AD18: =IF($AA18>$Z18,"เกินกำหนด","ทันกำหนด") -> ทันกำหนด
A19: 16 | B19: 46056 | C19: JC-0147-001-02 | D19: XAAR Multi-Tester 060 | E19: 8 | F19: 8 | G19: =$E19-$F19 -> 0 | H19: =IF($G19=0,"ครบ","ไม่ครบ") -> ครบ | I19: LATHE 1 | J19: =VLOOKUP(I19,Sheet2!$B$1:$C$9,2,FALSE) -> ชาญชัย | K19: 0.10416667 | M19: =VLOOKUP(L19,Sheet2!$B$1:$C$9,2,FALSE) -> #N/A | P19: =VLOOKUP(O19,Sheet2!$B$1:$C$9,2,FALSE) -> #N/A | S19: =VLOOKUP(R19,Sheet2!$B$1:$C$9,2,FALSE) -> #N/A | U19: =$K19+$N19+$Q19+$T19 -> 0.10416667 | Y19: คุณจักรกฤษณ์ | Z19: 46065 | AA19: 46056 | AB19: คุณจักรกฤษณ์ | AC19: 46087 | AD19: =IF($AA19>$Z19,"เกินกำหนด","ทันกำหนด") -> ทันกำหนด
A20: 17 | B20: 46056 | C20: JC-0147-001-03 | D20: XAAR Multi-Tester REV1.01 038 | E20: 2 | F20: 2 | G20: =$E20-$F20 -> 0 | H20: =IF($G20=0,"ครบ","ไม่ครบ") -> ครบ | I20: LATHE 1 | J20: =VLOOKUP(I20,Sheet2!$B$1:$C$9,2,FALSE) -> ชาญชัย | K20: 0.03125 | M20: =VLOOKUP(L20,Sheet2!$B$1:$C$9,2,FALSE) -> #N/A | P20: =VLOOKUP(O20,Sheet2!$B$1:$C$9,2,FALSE) -> #N/A | S20: =VLOOKUP(R20,Sheet2!$B$1:$C$9,2,FALSE) -> #N/A | U20: =$K20+$N20+$Q20+$T20 -> 0.03125 | Y20: คุณจักรกฤษณ์ | Z20: 46065 | AA20: 46056 | AB20: คุณจักรกฤษณ์ | AC20: 46087 | AD20: =IF($AA20>$Z20,"เกินกำหนด","ทันกำหนด") -> ทันกำหนด
A21: 18 | B21: 46056 | C21: JC-0147-001-04 | D21: XAAR Multi-Tester REV1.01 041 | E21: 16 | F21: 16 | G21: =$E21-$F21 -> 0 | H21: =IF($G21=0,"ครบ","ไม่ครบ") -> ครบ | I21: LATHE 1 | J21: =VLOOKUP(I21,Sheet2!$B$1:$C$9,2,FALSE) -> ชาญชัย | K21: 0.17361111 | M21: =VLOOKUP(L21,Sheet2!$B$1:$C$9,2,FALSE) -> #N/A | P21: =VLOOKUP(O21,Sheet2!$B$1:$C$9,2,FALSE) -> #N/A | S21: =VLOOKUP(R21,Sheet2!$B$1:$C$9,2,FALSE) -> #N/A | U21: =$K21+$N21+$Q21+$T21 -> 0.17361111 | Y21: คุณจักรกฤษณ์ | Z21: 46065 | AA21: 46057 | AB21: คุณจักรกฤษณ์ | AC21: 46087 | AD21: =IF($AA21>$Z21,"เกินกำหนด","ทันกำหนด") -> ทันกำหนด
A22: 19 | B22: 46056 | C22: JA-2712-001-01_ตัดแมท | D22: ตัดแมท NIKA 6x245x270 mm. | E22: 1 | F22: 1 | G22: =$E22-$F22 -> 0 | H22: =IF($G22=0,"ครบ","ไม่ครบ") -> ครบ | I22: SPAR | J22: =VLOOKUP(I22,Sheet2!$B$1:$C$9,2,FALSE) -> ธนาพล | K22: 0.020833333 | M22: =VLOOKUP(L22,Sheet2!$B$1:$C$9,2,FALSE) -> #N/A | P22: =VLOOKUP(O22,Sheet2!$B$1:$C$9,2,FALSE) -> #N/A | S22: =VLOOKUP(R22,Sheet2!$B$1:$C$9,2,FALSE) -> #N/A | U22: =$K22+$N22+$Q22+$T22 -> 0.020833333 | Y22: คุณจักรกฤษณ์ | Z22: 46057 | AA22: 46056 | AB22: คุณอารยา | AC22: 46057 | AD22: =IF($AA22>$Z22,"เกินกำหนด","ทันกำหนด") -> ทันกำหนด
A23: 20 | B23: 46056 | C23: JA-2667-003-01_Modify | D23: IPU KIT FOR M2070-011 Rev.1 | E23: 1 | F23: 1 | G23: =$E23-$F23 -> 0 | H23: =IF($G23=0,"ครบ","ไม่ครบ") -> ครบ | I23: ML 2 | J23: =VLOOKUP(I23,Sheet2!$B$1:$C$9,2,FALSE) -> จักรกฤษณ์ | K23: 0.010416667 | M23: =VLOOKUP(L23,Sheet2!$B$1:$C$9,2,FALSE) -> #N/A | P23: =VLOOKUP(O23,Sheet2!$B$1:$C$9,2,FALSE) -> #N/A | S23: =VLOOKUP(R23,Sheet2!$B$1:$C$9,2,FALSE) -> #N/A | U23: =$K23+$N23+$Q23+$T23 -> 0.010416667 | Y23: คุณยุทธนา | Z23: 46057 | AA23: 46057 | AB23: คุณยุทธนา | AC23: 46058 | AD23: =IF($AA23>$Z23,"เกินกำหนด","ทันกำหนด") -> ทันกำหนด
A24: 21 | B24: 46057 | C24: JA-2683-002-01_Modify | D24: IPU KIT FOR M2014-019 | E24: 1 | F24: 1 | G24: =$E24-$F24 -> 0 | H24: =IF($G24=0,"ครบ","ไม่ครบ") -> ครบ | I24: ML 1 | J24: =VLOOKUP(I24,Sheet2!$B$1:$C$9,2,FALSE) -> วินัย | K24: 0.024305556 | M24: =VLOOKUP(L24,Sheet2!$B$1:$C$9,2,FALSE) -> #N/A | P24: =VLOOKUP(O24,Sheet2!$B$1:$C$9,2,FALSE) -> #N/A | S24: =VLOOKUP(R24,Sheet2!$B$1:$C$9,2,FALSE) -> #N/A | U24: =$K24+$N24+$Q24+$T24 -> 0.024305556 | Y24: คุณปฐมพงษ์ | Z24: 46057 | AA24: 46057 | AB24: คุณปฐมพงษ์ | AC24: 46057 | AD24: =IF($AA24>$Z24,"เกินกำหนด","ทันกำหนด") -> ทันกำหนด
A25: 22 | B25: 46057 | C25: JE-0716-001-05 | D25: DRIVE ROLLER Di80 for BELT W400 | E25: 5 | F25: 5 | G25: =$E25-$F25 -> 0 | H25: =IF($G25=0,"ครบ","ไม่ครบ") -> ครบ | I25: LATHE 2 | J25: =VLOOKUP(I25,Sheet2!$B$1:$C$9,2,FALSE) -> สรายุทธ | K25: 0.013888889 | L25: ML 2 | M25: =VLOOKUP(L25,Sheet2!$B$1:$C$9,2,FALSE) -> จักรกฤษณ์ | N25: 0.125 | P25: =VLOOKUP(O25,Sheet2!$B$1:$C$9,2,FALSE) -> #N/A | S25: =VLOOKUP(R25,Sheet2!$B$1:$C$9,2,FALSE) -> #N/A | U25: =$K25+$N25+$Q25+$T25 -> 0.13888889 | Y25: คุณมนัสนันท์ | Z25: 46080 | AA25: 46069 | AB25: คุณมนัสนันท์ | AC25: 46079 | AD25: =IF($AA25>$Z25,"เกินกำหนด","ทันกำหนด") -> ทันกำหนด
A26: 23 | B26: 46057 | C26: JE-0716-001-06 | D26: TAIL ROLLER D50 for BELT W400 | E26: 5 | F26: 5 | G26: =$E26-$F26 -> 0 | H26: =IF($G26=0,"ครบ","ไม่ครบ") -> ครบ | I26: LATHE 2 | J26: =VLOOKUP(I26,Sheet2!$B$1:$C$9,2,FALSE) -> สรายุทธ | K26: 0.66666667 | M26: =VLOOKUP(L26,Sheet2!$B$1:$C$9,2,FALSE) -> #N/A | P26: =VLOOKUP(O26,Sheet2!$B$1:$C$9,2,FALSE) -> #N/A | S26: =VLOOKUP(R26,Sheet2!$B$1:$C$9,2,FALSE) -> #N/A | U26: =$K26+$N26+$Q26+$T26 -> 0.66666667 | X26: ชุบซิงค์ขาว | Y26: คุณมนัสนันท์ | Z26: 46080 | AA26: 46079 | AB26: คุณชาคริส | AC26: 46080 | AD26: =IF($AA26>$Z26,"เกินกำหนด","ทันกำหนด") -> ทันกำหนด
A27: 24 | B27: 46057 | C27: JE-0716-001-07 | D27: TAIL ROLLER Di50 with BRUSH for BELT W400 | E27: 5 | F27: 5 | G27: =$E27-$F27 -> 0 | H27: =IF($G27=0,"ครบ","ไม่ครบ") -> ครบ | I27: LATHE 2 | J27: =VLOOKUP(I27,Sheet2!$B$1:$C$9,2,FALSE) -> สรายุทธ | K27: 0.70833333 | L27: ML 2 | M27: =VLOOKUP(L27,Sheet2!$B$1:$C$9,2,FALSE) -> จักรกฤษณ์ | N27: 0.125 | P27: =VLOOKUP(O27,Sheet2!$B$1:$C$9,2,FALSE) -> #N/A | S27: =VLOOKUP(R27,Sheet2!$B$1:$C$9,2,FALSE) -> #N/A | U27: =$K27+$N27+$Q27+$T27 -> 0.83333333 | X27: ชุบซิงค์ขาว | Y27: คุณมนัสนันท์ | Z27: 46080 | AA27: 46079 | AB27: คุณชาคริส | AC27: 46080 | AD27: =IF($AA27>$Z27,"เกินกำหนด","ทันกำหนด") -> ทันกำหนด
A28: 25 | B28: 46057 | C28: JB-0381-003-01 | D28: ME-B0381-01-000-0103 | E28: 1 | F28: 1 | G28: =$E28-$F28 -> 0 | H28: =IF($G28=0,"ครบ","ไม่ครบ") -> ครบ | I28: SPAR | J28: =VLOOKUP(I28,Sheet2!$B$1:$C$9,2,FALSE) -> ธนาพล | K28: 0.041666667 | M28: =VLOOKUP(L28,Sheet2!$B$1:$C$9,2,FALSE) -> #N/A | P28: =VLOOKUP(O28,Sheet2!$B$1:$C$9,2,FALSE) -> #N/A | S28: =VLOOKUP(R28,Sheet2!$B$1:$C$9,2,FALSE) -> #N/A | U28: =$K28+$N28+$Q28+$T28 -> 0.041666667 | Y28: คุณอนุวัฒิ | Z28: 46072 | AA28: 46063 | AB28: ส่ง BU 2 | AC28: 46071 | AD28: =IF($AA28>$Z28,"เกินกำหนด","ทันกำหนด") -> ทันกำหนด
A29: 26 | B29: 46057 | C29: JB-0381-003-02 | D29: ME-B0381-01-000-0109 | E29: 2 | F29: 2 | G29: =$E29-$F29 -> 0 | H29: =IF($G29=0,"ครบ","ไม่ครบ") -> ครบ | I29: SPAR | J29: =VLOOKUP(I29,Sheet2!$B$1:$C$9,2,FALSE) -> ธนาพล | K29: 0.0625 | M29: =VLOOKUP(L29,Sheet2!$B$1:$C$9,2,FALSE) -> #N/A | P29: =VLOOKUP(O29,Sheet2!$B$1:$C$9,2,FALSE) -> #N/A | S29: =VLOOKUP(R29,Sheet2!$B$1:$C$9,2,FALSE) -> #N/A | U29: =$K29+$N29+$Q29+$T29 -> 0.0625 | Y29: คุณอนุวัฒิ | Z29: 46072 | AA29: 46063 | AB29: ส่ง BU 2 | AC29: 46071 | AD29: =IF($AA29>$Z29,"เกินกำหนด","ทันกำหนด") -> ทันกำหนด
A30: 27 | B30: 46057 | C30: JB-0381-003-03 | D30: ME-B0381-01-000-0137 | E30: 2 | F30: 2 | G30: =$E30-$F30 -> 0 | H30: =IF($G30=0,"ครบ","ไม่ครบ") -> ครบ | I30: SPAR | J30: =VLOOKUP(I30,Sheet2!$B$1:$C$9,2,FALSE) -> ธนาพล | K30: 0.041666667 | M30: =VLOOKUP(L30,Sheet2!$B$1:$C$9,2,FALSE) -> #N/A | P30: =VLOOKUP(O30,Sheet2!$B$1:$C$9,2,FALSE) -> #N/A | S30: =VLOOKUP(R30,Sheet2!$B$1:$C$9,2,FALSE) -> #N/A | U30: =$K30+$N30+$Q30+$T30 -> 0.041666667 | Y30: คุณอนุวัฒิ | Z30: 46072 | AA30: 46063 | AB30: ส่ง BU 2 | AC30: 46071 | AD30: =IF($AA30>$Z30,"เกินกำหนด","ทันกำหนด") -> ทันกำหนด
A31: 28 | B31: 46057 | C31: JB-0381-003-04 | D31: ME-B0381-01-000-0138 | E31: 2 | F31: 2 | G31: =$E31-$F31 -> 0 | H31: =IF($G31=0,"ครบ","ไม่ครบ") -> ครบ | I31: SPAR | J31: =VLOOKUP(I31,Sheet2!$B$1:$C$9,2,FALSE) -> ธนาพล | K31: 0.041666667 | M31: =VLOOKUP(L31,Sheet2!$B$1:$C$9,2,FALSE) -> #N/A | P31: =VLOOKUP(O31,Sheet2!$B$1:$C$9,2,FALSE) -> #N/A | S31: =VLOOKUP(R31,Sheet2!$B$1:$C$9,2,FALSE) -> #N/A | U31: =$K31+$N31+$Q31+$T31 -> 0.041666667 | Y31: คุณอนุวัฒิ | Z31: 46072 | AA31: 46063 | AB31: ส่ง BU 2 | AC31: 46071 | AD31: =IF($AA31>$Z31,"เกินกำหนด","ทันกำหนด") -> ทันกำหนด
A32: 29 | B32: 46057 | C32: JB-0381-003-05 | D32: ME-B0381-01-000-0139 | E32: 2 | F32: 2 | G32: =$E32-$F32 -> 0 | H32: =IF($G32=0,"ครบ","ไม่ครบ") -> ครบ | I32: SPAR | J32: =VLOOKUP(I32,Sheet2!$B$1:$C$9,2,FALSE) -> ธนาพล | K32: 0.020833333 | M32: =VLOOKUP(L32,Sheet2!$B$1:$C$9,2,FALSE) -> #N/A | P32: =VLOOKUP(O32,Sheet2!$B$1:$C$9,2,FALSE) -> #N/A | S32: =VLOOKUP(R32,Sheet2!$B$1:$C$9,2,FALSE) -> #N/A | U32: =$K32+$N32+$Q32+$T32 -> 0.020833333 | Y32: คุณอนุวัฒิ | Z32: 46072 | AA32: 46063 | AB32: ส่ง BU 2 | AC32: 46071 | AD32: =IF($AA32>$Z32,"เกินกำหนด","ทันกำหนด") -> ทันกำหนด
A33: 30 | B33: 46057 | C33: JB-0381-003-06 | D33: ME-B0381-01-000-0147 | E33: 1 | F33: 1 | G33: =$E33-$F33 -> 0 | H33: =IF($G33=0,"ครบ","ไม่ครบ") -> ครบ | I33: SPAR | J33: =VLOOKUP(I33,Sheet2!$B$1:$C$9,2,FALSE) -> ธนาพล | K33: 0.041666667 | L33: CAM 1 | M33: =VLOOKUP(L33,Sheet2!$B$1:$C$9,2,FALSE) -> เพลินชัย | N33: 0.034722222 | O33: CNC 2 | P33: รังสรรค์ | Q33: 0.083333333 | S33: =VLOOKUP(R33,Sheet2!$B$1:$C$9,2,FALSE) -> #N/A | U33: =$K33+$N33+$Q33+$T33 -> 0.15972222 | Y33: คุณอนุวัฒิ | Z33: 46072 | AA33: 46062 | AB33: ส่ง BU 2 | AC33: 46071 | AD33: =IF($AA33>$Z33,"เกินกำหนด","ทันกำหนด") -> ทันกำหนด
A34: 31 | B34: 46057 | C34: JB-0381-003-07 | D34: ME-B0381-01-000-0154 | E34: 2 | F34: 2 | G34: =$E34-$F34 -> 0 | H34: =IF($G34=0,"ครบ","ไม่ครบ") -> ครบ | I34: SPAR | J34: =VLOOKUP(I34,Sheet2!$B$1:$C$9,2,FALSE) -> ธนาพล | K34: 0.048611111 | M34: =VLOOKUP(L34,Sheet2!$B$1:$C$9,2,FALSE) -> #N/A | P34: =VLOOKUP(O34,Sheet2!$B$1:$C$9,2,FALSE) -> #N/A | S34: =VLOOKUP(R34,Sheet2!$B$1:$C$9,2,FALSE) -> #N/A | U34: =$K34+$N34+$Q34+$T34 -> 0.048611111 | Y34: คุณอนุวัฒิ | Z34: 46072 | AA34: 46064 | AB34: ส่ง BU 2 | AC34: 46071 | AD34: =IF($AA34>$Z34,"เกินกำหนด","ทันกำหนด") -> ทันกำหนด
A35: 32 | B35: 46057 | C35: JB-0381-003-08 | D35: ME-B0381-01-000-0155 | E35: 2 | F35: 2 | G35: =$E35-$F35 -> 0 | H35: =IF($G35=0,"ครบ","ไม่ครบ") -> ครบ | I35: SPAR | J35: =VLOOKUP(I35,Sheet2!$B$1:$C$9,2,FALSE) -> ธนาพล | K35: 0.041666667 | M35: =VLOOKUP(L35,Sheet2!$B$1:$C$9,2,FALSE) -> #N/A | P35: =VLOOKUP(O35,Sheet2!$B$1:$C$9,2,FALSE) -> #N/A | S35: =VLOOKUP(R35,Sheet2!$B$1:$C$9,2,FALSE) -> #N/A | U35: =$K35+$N35+$Q35+$T35 -> 0.041666667 | Y35: คุณอนุวัฒิ | Z35: 46072 | AA35: 46064 | AB35: ส่ง BU 2 | AC35: 46071 | AD35: =IF($AA35>$Z35,"เกินกำหนด","ทันกำหนด") -> ทันกำหนด
A36: 33 | B36: 46057 | C36: JB-0381-003-09 | D36: ME-B0381-01-000-0196 | E36: 2 | F36: 2 | G36: =$E36-$F36 -> 0 | H36: =IF($G36=0,"ครบ","ไม่ครบ") -> ครบ | I36: SPAR | J36: =VLOOKUP(I36,Sheet2!$B$1:$C$9,2,FALSE) -> ธนาพล | K36: 0.041666667 | M36: =VLOOKUP(L36,Sheet2!$B$1:$C$9,2,FALSE) -> #N/A | P36: =VLOOKUP(O36,Sheet2!$B$1:$C$9,2,FALSE) -> #N/A | S36: =VLOOKUP(R36,Sheet2!$B$1:$C$9,2,FALSE) -> #N/A | U36: =$K36+$N36+$Q36+$T36 -> 0.041666667 | Y36: คุณอนุวัฒิ | Z36: 46072 | AA36: 46064 | AB36: ส่ง BU 2 | AC36: 46071 | AD36: =IF($AA36>$Z36,"เกินกำหนด","ทันกำหนด") -> ทันกำหนด
A37: 34 | B37: 46057 | C37: JA-2710-001-01 | D37: LA0001-080001-01 | E37: 4 | F37: 4 | G37: =$E37-$F37 -> 0 | H37: =IF($G37=0,"ครบ","ไม่ครบ") -> ครบ | I37: SPAR | J37: =VLOOKUP(I37,Sheet2!$B$1:$C$9,2,FALSE) -> ธนาพล | K37: 0.16666667 | M37: =VLOOKUP(L37,Sheet2!$B$1:$C$9,2,FALSE) -> #N/A | P37: =VLOOKUP(O37,Sheet2!$B$1:$C$9,2,FALSE) -> #N/A | S37: =VLOOKUP(R37,Sheet2!$B$1:$C$9,2,FALSE) -> #N/A | U37: =$K37+$N37+$Q37+$T37 -> 0.16666667 | Y37: คุณยุทธนา | Z37: 46078 | AA37: 46076 | AB37: คุณยุทธนา | AC37: 46079 | AD37: =IF($AA37>$Z37,"เกินกำหนด","ทันกำหนด") -> ทันกำหนด
A38: 35 | B38: 46057 | C38: JA-2710-001-02 | D38: LA2306-010107-00 | E38: 4 | F38: 4 | G38: =$E38-$F38 -> 0 | H38: =IF($G38=0,"ครบ","ไม่ครบ") -> ครบ | I38: LATHE 1 | J38: =VLOOKUP(I38,Sheet2!$B$1:$C$9,2,FALSE) -> ชาญชัย | K38: 0.090277778 | L38: ML 1 | M38: =VLOOKUP(L38,Sheet2!$B$1:$C$9,2,FALSE) -> วินัย | N38: 0.086805556 | P38: =VLOOKUP(O38,Sheet2!$B$1:$C$9,2,FALSE) -> #N/A | S38: =VLOOKUP(R38,Sheet2!$B$1:$C$9,2,FALSE) -> #N/A | U38: =$K38+$N38+$Q38+$T38 -> 0.17708333 | X38: อโนไดซ์ขาว | Y38: คุณยุทธนา | Z38: 46090 | AA38: 46085 | AB38: คุณธนภูมิ | AC38: 46087 | AD38: =IF($AA38>$Z38,"เกินกำหนด","ทันกำหนด") -> ทันกำหนด
A39: 36 | B39: 46057 | C39: JA-2710-001-03 | D39: LA3517-000001-00 | E39: 2 | F39: 2 | G39: =$E39-$F39 -> 0 | H39: =IF($G39=0,"ครบ","ไม่ครบ") -> ครบ | I39: LATHE 1 | J39: =VLOOKUP(I39,Sheet2!$B$1:$C$9,2,FALSE) -> ชาญชัย | K39: 0.048611111 | M39: =VLOOKUP(L39,Sheet2!$B$1:$C$9,2,FALSE) -> #N/A | P39: =VLOOKUP(O39,Sheet2!$B$1:$C$9,2,FALSE) -> #N/A | S39: =VLOOKUP(R39,Sheet2!$B$1:$C$9,2,FALSE) -> #N/A | U39: =$K39+$N39+$Q39+$T39 -> 0.048611111 | Y39: คุณยุทธนา | Z39: 46090 | AA39: 46064 | AB39: คุณธนภูมิ | AC39: 46093 | AD39: =IF($AA39>$Z39,"เกินกำหนด","ทันกำหนด") -> ทันกำหนด
A40: 37 | B40: 46057 | C40: JA-2710-001-04 | D40: LA3517-000002-00 | E40: 2 | F40: 2 | G40: =$E40-$F40 -> 0 | H40: =IF($G40=0,"ครบ","ไม่ครบ") -> ครบ | I40: LATHE 1 | J40: =VLOOKUP(I40,Sheet2!$B$1:$C$9,2,FALSE) -> ชาญชัย | K40: 0.0625 | M40: =VLOOKUP(L40,Sheet2!$B$1:$C$9,2,FALSE) -> #N/A | P40: =VLOOKUP(O40,Sheet2!$B$1:$C$9,2,FALSE) -> #N/A | S40: =VLOOKUP(R40,Sheet2!$B$1:$C$9,2,FALSE) -> #N/A | U40: =$K40+$N40+$Q40+$T40 -> 0.0625 | Y40: คุณยุทธนา | Z40: 46090 | AA40: 46064 | AB40: คุณธนภูมิ | AC40: 46093 | AD40: =IF($AA40>$Z40,"เกินกำหนด","ทันกำหนด") -> ทันกำหนด
...

Sheet Sheet2
B1: CAM 1 | C1: เพลินชัย | D1: Grinding | E1: อโนไดซ์
B2: CAM 2 | C2: สุขสันต์ | D2: Wire cut | E2: อโนไดซ์ดำ
B3: CAM 3 | C3: รังสรรค์ | D3: Waterjet | E3: อโนไดซ์ขาว
B4: ML 1 | C4: วินัย | D4: EDM | E4: ฮาร์ดอโนไดซ์
B5: ML 2 | C5: จักรกฤษณ์ | D5: CNC-Late | E5: ชุบแข็ง
B6: ML 3 | C6: สรายุทธ | D6: Weldding | E6: ชุบซิงค์ขาว
B7: LATHE 1 | C7: ชาญชัย | E7: ชุบซิงค์ดำ
B8: LATHE 2 | C8: สรายุทธ | E8: ชุบฮาร์ดโครม
B9: SPAR | C9: ธนาพล | E9: ชุบนิเกิล
E10: รมดำ
B11: CAM 1 | C11: เพลินชัย | E11: แฟลชโครม
B12: CAM 2 | C12: สุขสันต์ | E12: โครเมี่ยม
B13: CAM 3 | C13: รังสรรค์
B14: ML 1 | C14: จักรกฤษณ์
B15: ML 2 | C15: ชาญชัย
B16: ML 3 | C16: สรายุทธ
B17: LATHE 1 | C17: ชาญชัย
B18: LATHE 2 | C18: สรายุทธ
B19: SPAR | C19: ธีรณัฐ
B21: CAM 1 | C21: เพลินชัย
B22: CAM 2 | C22: สุขสันต์
B23: CAM 3 | C23: รังสรรค์
B24: ML 1 | C24: วินัย
B25: ML 2 | C25: จักรกฤษณ์
... B29: SPAR | C29: ธีรณัฐ
