Workbook

Sheet Template
A1: Status On Plan Work Shop
A2: ลำดับ | B2: วันที่ | C2: JOB | D2: DWG.Name | E2: จำนวนชิ้น | F2: เสร็จแล้ว | G2: ยังไม่เสร็จ | H2: สถานะ | I2: PROCESS | J2: ผู้รับผิดชอบ | K2: เวลา/ช.ม/นาที | L2: PROCESS | M2: ผู้รับผิดชอบ | N2: เวลา/ช.ม/นาที | O2: PROCESS | P2: ผู้รับผิดชอบ | Q2: เวลา/ช.ม/นาที | R2: PROCESS | S2: ผู้รับผิดชอบ | T2: เวลา/ช.ม/นาที | U2: เวลารวม | V2: OUTSOURCE | Y2: ผู้ส่งแบบ | Z2: กำหนดส่ง | AA2: วันเสร็จจริง | AB2: ผู้รับ | AC2: วันที่รับ | AD2: KPI ส่งมอบ | AE2: แก้ไข(ชิ้น) | AG2: ราคาแมท ขึ้นใหม่ | AH2: Remark
A3: ลำดับ | B3: วันที่ | C3: JOB | D3: DWG.Name | E3: จำนวนชิ้น | F3: เสร็จแล้ว | G3: ยังไม่เสร็จ | H3: สถานะ | I3: PROCESS | J3: ผู้รับผิดชอบ | K3: เวลา/ช.ม/นาที | L3: PROCESS | M3: ผู้รับผิดชอบ | N3: เวลา/ช.ม/นาที | O3: PROCESS | P3: ผู้รับผิดชอบ | Q3: เวลา/ช.ม/นาที | R3: PROCESS | S3: ผู้รับผิดชอบ | T3: เวลา/ช.ม/นาที | U3: เวลารวม | V3: Process | W3: Process | X3: Coating /Heat Treatment | Y3: ผู้ส่งแบบ | Z3: กำหนดส่ง | AA3: วันเสร็จจริง | AB3: ผู้รับ | AC3: วันที่รับ | AE3: แก้ไขได้ | AF3: ขึ้นใหม่
A4: 1 | G4: =$E4-$F4 -> 0 | H4: =IF($G4=0,"ครบ","ไม่ครบ") -> ครบ | J4: =VLOOKUP(I4,Sheet2!$B$10:$C$18,2,FALSE) -> #N/A | M4: =VLOOKUP(L4,Sheet2!$B$10:$C$18,2,FALSE) -> #N/A | P4: =VLOOKUP(O4,Sheet2!$B$10:$C$18,2,FALSE) -> #N/A | S4: =VLOOKUP(R4,Sheet2!$B$10:$C$18,2,FALSE) -> #N/A | U4: =$K4+$N4+$Q4+$T4 -> 0 | AD4: =IF($AA4>$Z4,"เกินกำหนด","ทันกำหนด") -> ทันกำหนด
A5: 2 | G5: =$E5-$F5 -> 0 | H5: =IF($G5=0,"ครบ","ไม่ครบ") -> ครบ | J5: =VLOOKUP(I5,Sheet2!$B$10:$C$18,2,FALSE) -> #N/A | M5: =VLOOKUP(L5,Sheet2!$B$10:$C$18,2,FALSE) -> #N/A | P5: =VLOOKUP(O5,Sheet2!$B$10:$C$18,2,FALSE) -> #N/A | S5: =VLOOKUP(R5,Sheet2!$B$10:$C$18,2,FALSE) -> #N/A | U5: =$K5+$N5+$Q5+$T5 -> 0 | AD5: =IF($AA5>$Z5,"เกินกำหนด","ทันกำหนด") -> ทันกำหนด
A6: 3 | G6: =$E6-$F6 -> 0 | H6: =IF($G6=0,"ครบ","ไม่ครบ") -> ครบ | J6: =VLOOKUP(I6,Sheet2!$B$10:$C$18,2,FALSE) -> #N/A | M6: =VLOOKUP(L6,Sheet2!$B$10:$C$18,2,FALSE) -> #N/A | P6: =VLOOKUP(O6,Sheet2!$B$10:$C$18,2,FALSE) -> #N/A | S6: =VLOOKUP(R6,Sheet2!$B$10:$C$18,2,FALSE) -> #N/A | U6: =$K6+$N6+$Q6+$T6 -> 0 | AD6: =IF($AA6>$Z6,"เกินกำหนด","ทันกำหนด") -> ทันกำหนด
A7: 4 | G7: =$E7-$F7 -> 0 | H7: =IF($G7=0,"ครบ","ไม่ครบ") -> ครบ | J7: =VLOOKUP(I7,Sheet2!$B$10:$C$18,2,FALSE) -> #N/A | M7: =VLOOKUP(L7,Sheet2!$B$10:$C$18,2,FALSE) -> #N/A | P7: =VLOOKUP(O7,Sheet2!$B$10:$C$18,2,FALSE) -> #N/A | S7: =VLOOKUP(R7,Sheet2!$B$10:$C$18,2,FALSE) -> #N/A | U7: =$K7+$N7+$Q7+$T7 -> 0 | AD7: =IF($AA7>$Z7,"เกินกำหนด","ทันกำหนด") -> ทันกำหนด
A8: 5 | G8: =$E8-$F8 -> 0 | H8: =IF($G8=0,"ครบ","ไม่ครบ") -> ครบ | J8: =VLOOKUP(I8,Sheet2!$B$10:$C$18,2,FALSE) -> #N/A | M8: =VLOOKUP(L8,Sheet2!$B$10:$C$18,2,FALSE) -> #N/A | P8: =VLOOKUP(O8,Sheet2!$B$10:$C$18,2,FALSE) -> #N/A | S8: =VLOOKUP(R8,Sheet2!$B$10:$C$18,2,FALSE) -> #N/A | U8: =$K8+$N8+$Q8+$T8 -> 0 | AD8: =IF($AA8>$Z8,"เกินกำหนด","ทันกำหนด") -> ทันกำหนด
A9: 6 | G9: =$E9-$F9 -> 0 | H9: =IF($G9=0,"ครบ","ไม่ครบ") -> ครบ | J9: =VLOOKUP(I9,Sheet2!$B$10:$C$18,2,FALSE) -> #N/A | M9: =VLOOKUP(L9,Sheet2!$B$10:$C$18,2,FALSE) -> #N/A | P9: =VLOOKUP(O9,Sheet2!$B$10:$C$18,2,FALSE) -> #N/A | S9: =VLOOKUP(R9,Sheet2!$B$10:$C$18,2,FALSE) -> #N/A | U9: =$K9+$N9+$Q9+$T9 -> 0 | AD9: =IF($AA9>$Z9,"เกินกำหนด","ทันกำหนด") -> ทันกำหนด
A10: 7 | G10: =$E10-$F10 -> 0 | H10: =IF($G10=0,"ครบ","ไม่ครบ") -> ครบ | J10: =VLOOKUP(I10,Sheet2!$B$10:$C$18,2,FALSE) -> #N/A | M10: =VLOOKUP(L10,Sheet2!$B$10:$C$18,2,FALSE) -> #N/A | P10: =VLOOKUP(O10,Sheet2!$B$10:$C$18,2,FALSE) -> #N/A | S10: =VLOOKUP(R10,Sheet2!$B$10:$C$18,2,FALSE) -> #N/A | U10: =$K10+$N10+$Q10+$T10 -> 0 | AD10: =IF($AA10>$Z10,"เกินกำหนด","ทันกำหนด") -> ทันกำหนด
A11: 8 | G11: =$E11-$F11 -> 0 | H11: =IF($G11=0,"ครบ","ไม่ครบ") -> ครบ | J11: =VLOOKUP(I11,Sheet2!$B$10:$C$18,2,FALSE) -> #N/A | M11: =VLOOKUP(L11,Sheet2!$B$10:$C$18,2,FALSE) -> #N/A | P11: =VLOOKUP(O11,Sheet2!$B$10:$C$18,2,FALSE) -> #N/A | S11: =VLOOKUP(R11,Sheet2!$B$10:$C$18,2,FALSE) -> #N/A | U11: =$K11+$N11+$Q11+$T11 -> 0 | AD11: =IF($AA11>$Z11,"เกินกำหนด","ทันกำหนด") -> ทันกำหนด
A12: 9 | G12: =$E12-$F12 -> 0 | H12: =IF($G12=0,"ครบ","ไม่ครบ") -> ครบ | J12: =VLOOKUP(I12,Sheet2!$B$10:$C$18,2,FALSE) -> #N/A | M12: =VLOOKUP(L12,Sheet2!$B$10:$C$18,2,FALSE) -> #N/A | P12: =VLOOKUP(O12,Sheet2!$B$10:$C$18,2,FALSE) -> #N/A | S12: =VLOOKUP(R12,Sheet2!$B$10:$C$18,2,FALSE) -> #N/A | U12: =$K12+$N12+$Q12+$T12 -> 0 | AD12: =IF($AA12>$Z12,"เกินกำหนด","ทันกำหนด") -> ทันกำหนด
A13: 10 | G13: =$E13-$F13 -> 0 | H13: =IF($G13=0,"ครบ","ไม่ครบ") -> ครบ | J13: =VLOOKUP(I13,Sheet2!$B$10:$C$18,2,FALSE) -> #N/A | M13: =VLOOKUP(L13,Sheet2!$B$10:$C$18,2,FALSE) -> #N/A | P13: =VLOOKUP(O13,Sheet2!$B$10:$C$18,2,FALSE) -> #N/A | S13: =VLOOKUP(R13,Sheet2!$B$10:$C$18,2,FALSE) -> #N/A | U13: =$K13+$N13+$Q13+$T13 -> 0 | AD13: =IF($AA13>$Z13,"เกินกำหนด","ทันกำหนด") -> ทันกำหนด
A14: 11 | G14: =$E14-$F14 -> 0 | H14: =IF($G14=0,"ครบ","ไม่ครบ") -> ครบ | J14: =VLOOKUP(I14,Sheet2!$B$10:$C$18,2,FALSE) -> #N/A | M14: =VLOOKUP(L14,Sheet2!$B$10:$C$18,2,FALSE) -> #N/A | P14: =VLOOKUP(O14,Sheet2!$B$10:$C$18,2,FALSE) -> #N/A | S14: =VLOOKUP(R14,Sheet2!$B$10:$C$18,2,FALSE) -> #N/A | U14: =$K14+$N14+$Q14+$T14 -> 0 | AD14: =IF($AA14>$Z14,"เกินกำหนด","ทันกำหนด") -> ทันกำหนด
A15: 12 | G15: =$E15-$F15 -> 0 | H15: =IF($G15=0,"ครบ","ไม่ครบ") -> ครบ | J15: =VLOOKUP(I15,Sheet2!$B$10:$C$18,2,FALSE) -> #N/A | M15: =VLOOKUP(L15,Sheet2!$B$10:$C$18,2,FALSE) -> #N/A | P15: =VLOOKUP(O15,Sheet2!$B$10:$C$18,2,FALSE) -> #N/A | S15: =VLOOKUP(R15,Sheet2!$B$10:$C$18,2,FALSE) -> #N/A | U15: =$K15+$N15+$Q15+$T15 -> 0 | AD15: =IF($AA15>$Z15,"เกินกำหนด","ทันกำหนด") -> ทันกำหนด
... A603: 600 | G603: =$E603-$F603 -> 0 | H603: =IF($G603=0,"ครบ","ไม่ครบ") -> ครบ | J603: =VLOOKUP(I603,Sheet2!$B$10:$C$18,2,FALSE) -> #N/A | M603: =VLOOKUP(L603,Sheet2!$B$10:$C$18,2,FALSE) -> #N/A | P603: =VLOOKUP(O603,Sheet2!$B$10:$C$18,2,FALSE) -> #N/A | S603: =VLOOKUP(R603,Sheet2!$B$10:$C$18,2,FALSE) -> #N/A | U603: =$K603+$N603+$Q603+$T603 -> 0 | AD603: =IF($AA603>$Z603,"เกินกำหนด","ทันกำหนด") -> ทันกำหนด
C604: =SUBTOTAL(103,C4:C603) -> 0 | E604: =SUBTOTAL(9,E4:E603) -> 0 | AD604: =COUNTIF($AD$4:$AD603,"เกินกำหนด") -> 0 | AE604: =SUM(AE4:AE603) -> 0 | AF604: =SUM(AF4:AF603) -> 0 | AG604: =SUM(AG4:AG603) -> 0
C606: จำนวนแบบทั้งหมด (DWG) | D606: =C604 -> 0
C607: จำนวนชิ้นงานทั้งหมด (ชิ้น) | D607: =E604 -> 0
C608: จำนวนงานที่ส่งเกินกำหนด (DWG) | D608: =AD604 -> 0
C609: จำนวนงานที่ส่งตามกำหนด (DWG) | D609: =$D606-$D608 -> 0
C610: จำนวนงานที่ผิดพลาด (DWG) | D610: =AE604 -> 0
C611: KPI ส่งมอบ มากกว่า 90 % | D611: =($D609/$D606)*100 -> #DIV/0! | E611: =IF(D611>=90,"ผ่าน","ไม่ผ่าน") -> #DIV/0!
C612: KPI งานผิดพลาด น้อยกว่า 5 % | D612: =($D610/$D607)*100 -> #DIV/0! | E612: =IF(D612<=5,"ผ่าน","ไม่ผ่าน") -> #DIV/0!
C616: =SUBTOTAL(103,C4:C603) -> 0 | E616: =SUBTOTAL(9,E4:E603) -> 0
D618: \

Sheet ต.ค.69
A1: Status On Plan Work Shop
A2: ลำดับ | B2: วันที่ | C2: กำหนดส่ง | D2: JOB | E2: DWG.Name | F2: จำนวนชิ้น | G2: ผู้ส่งแบบ | H2: OUTSOURCE | K2: Remark
A3: ลำดับ | B3: วันที่ | C3: กำหนดส่ง | D3: JOB | E3: DWG.Name | F3: จำนวนชิ้น | G3: ผู้ส่งแบบ | H3: Process | I3: Process | J3: Coating /Heat Treatment
A4: 1 | B4: 46296 | C4: 46301 | D4: JA-2774-005-01-Modify | E4: Top 010 | F4: 4 | G4: คุณปณิธาน
A5: 2 | B5: 46296 | C5: 244631 | D5: JA-2919-003-01 | E5: MXS8-30ASBT-M9NLB_1 | F5: 4 | G5: คุณปฐมพงษ์ | J5: C/A
A6: 3 | B6: 46296 | C6: 244631 | D6: JA-2919-003-02 | E6: MXS-BT16-50_AOP-BM_0__1 | F6: 2 | G6: คุณปฐมพงษ์ | J6: C/A
A7: 4 | B7: 01/10/2569 | C7: 02/10/2569 | D7: JA-2926-002-01-Modify | E7: FCT FIXTURE MODEL M5843-13 | F7: 4 | G7: คุณปฐมพงษ์
A8: 5 | B8: 01/10/2569 | C8: 02/10/2569 | D8: JA-2926-002-02-Modify | E8: FCT FIXTURE MODEL M5843-19 | F8: 4 | G8: คุณปฐมพงษ์
A9: 6 | B9: 01/10/2569 | C9: 08/10/2569 | D9: JA-2940-001-01 | E9: FCT FIXTURE MODEL M5843-19 | F9: 32 | G9: คุณปฐมพงษ์
A10: 7 | B10: 01/10/2569 | C10: 01/10/2569 | D10: JA-2943-001-01-Modify | E10: Top 010 | F10: 12 | G10: คุณปณิธาน
A11: 8 | B11: 01/10/2569 | C11: 15/10/2569 | D11: JD-0885-001-01 | E11: MATTEL-ALB-0C-17 - DRAWING | F11: 2 | G11: คุณฑาริกา
A12: 9 | B12: 01/10/2569 | C12: 09/10/2569 | D12: JD-0886-001-01 | E12: b-gn0184-a01002-00 | F12: 1 | G12: คุณฑาริกา | J12: C/A
A13: 10 | B13: 01/10/2569 | C13: 09/10/2569 | D13: JD-0886-001-02 | E13: b-gn0184-a01003-00 | F13: 1 | G13: คุณฑาริกา
A14: 11 | B14: 01/10/2569 | C14: 09/10/2569 | D14: JD-0886-001-03 | E14: b-gn0184-a01004-00 | F14: 2 | G14: คุณฑาริกา
A15: 12 | B15: 01/10/2569 | C15: 09/10/2569 | D15: JD-0886-001-04 | E15: b-gn0184-a01005-00 | F15: 2 | G15: คุณฑาริกา
A16: 13 | B16: 01/10/2569 | C16: 09/10/2569 | D16: JD-0886-001-05 | E16: b-gn0184-a01006-00 | F16: 1 | G16: คุณฑาริกา | J16: B/A
A17: 14 | B17: 01/10/2569 | C17: 09/10/2569 | D17: JD-0886-001-06 | E17: b-gn0184-a01007-00 | F17: 1 | G17: คุณฑาริกา
A18: 15 | B18: 01/10/2569 | C18: 09/10/2569 | D18: JD-0886-001-07 | E18: b-gn0184-a01008-00 | F18: 1 | G18: คุณฑาริกา
A19: 16 | B19: 01/10/2569 | C19: 09/10/2569 | D19: JD-0886-001-08 | E19: b-gn0184-a01009-00 | F19: 2 | G19: คุณฑาริกา
A20: 17 | B20: 01/10/2569 | C20: 09/10/2569 | D20: JD-0886-001-09 | E20: b-gn0184-a01010-00 | F20: 1 | G20: คุณฑาริกา
A21: 18 | B21: 01/10/2569 | C21: 09/10/2569 | D21: JD-0886-001-10 | E21: b-gn0184-a01012-00 | F21: 1 | G21: คุณฑาริกา | J21: C/A
A22: 19 | B22: 01/10/2569 | C22: 09/10/2569 | D22: JD-0886-001-11 | E22: b-gn0184-a01013-00 | F22: 2 | G22: คุณฑาริกา | J22: C/A
A23: 20 | B23: 01/10/2569 | C23: 09/10/2569 | D23: JD-0886-001-12 | E23: b-gn0184-a01014-00 | F23: 1 | G23: คุณฑาริกา
A24: 21 | B24: 01/10/2569 | C24: 09/10/2569 | D24: JD-0886-001-13 | E24: b-gn0184-a01016-00 | F24: 1 | G24: คุณฑาริกา | J24: B/A
A25: 22 | B25: 01/10/2569 | C25: 09/10/2569 | D25: JD-0886-001-14 | E25: b-gn0184-a01101-00 | F25: 1 | G25: คุณฑาริกา | J25: C/A
A26: 23 | B26: 01/10/2569 | C26: 09/10/2569 | D26: JD-0887-001-01 | E26: B-GN0184-A01018-00 | F26: 1 | G26: คุณฑาริกา
A27: 24 | B27: 01/10/2569 | C27: 09/10/2569 | D27: JD-0887-002-01 | E27: b-gn0184-a01002-00 | F27: 1 | G27: คุณฑาริกา | J27: C/A
A28: 25 | B28: 01/10/2569 | C28: 09/10/2569 | D28: JD-0887-002-02 | E28: b-gn0184-a01003-00 | F28: 1 | G28: คุณฑาริกา
A29: 26 | B29: 01/10/2569 | C29: 09/10/2569 | D29: JD-0887-002-03 | E29: b-gn0184-a01004-00 | F29: 2 | G29: คุณฑาริกา
A30: 27 | B30: 01/10/2569 | C30: 09/10/2569 | D30: JD-0887-002-04 | E30: b-gn0184-a01005-00 | F30: 2 | G30: คุณฑาริกา
A31: 28 | B31: 01/10/2569 | C31: 09/10/2569 | D31: JD-0887-002-05 | E31: b-gn0184-a01006-00 | F31: 1 | G31: คุณฑาริกา | J31: B/A
A32: 29 | B32: 01/10/2569 | C32: 09/10/2569 | D32: JD-0887-002-06 | E32: b-gn0184-a01007-00 | F32: 1 | G32: คุณฑาริกา
A33: 30 | B33: 01/10/2569 | C33: 09/10/2569 | D33: JD-0887-002-07 | E33: b-gn0184-a01008-00 | F33: 1 | G33: คุณฑาริกา
A34: 31 | B34: 01/10/2569 | C34: 09/10/2569 | D34: JD-0887-002-08 | E34: b-gn0184-a01009-00 | F34: 2 | G34: คุณฑาริกา
A35: 32 | B35: 01/10/2569 | C35: 09/10/2569 | D35: JD-0887-002-09 | E35: b-gn0184-a01010-00 | F35: 1 | G35: คุณฑาริกา
A36: 33 | B36: 01/10/2569 | C36: 09/10/2569 | D36: JD-0887-002-10 | E36: b-gn0184-a01012-00 | F36: 1 | G36: คุณฑาริกา | J36: C/A
A37: 34 | B37: 01/10/2569 | C37: 09/10/2569 | D37: JD-0887-002-11 | E37: b-gn0184-a01013-00 | F37: 2 | G37: คุณฑาริกา | J37: C/A
A38: 35 | B38: 01/10/2569 | C38: 09/10/2569 | D38: JD-0887-002-12 | E38: b-gn0184-a01014-00 | F38: 1 | G38: คุณฑาริกา
A39: 36 | B39: 01/10/2569 | C39: 09/10/2569 | D39: JD-0887-002-13 | E39: b-gn0184-a01016-00 | F39: 1 | G39: คุณฑาริกา | J39: B/A
A40: 37 | B40: 01/10/2569 | C40: 09/10/2569 | D40: JD-0887-002-14 | E40: b-gn0184-a01101-00 | F40: 1 | G40: คุณฑาริกา | J40: C/A
...

Sheet DECEMBER
A1: Status On Plan Work Shop
A2: ลำดับ | B2: วันที่ | C2: JOB | D2: DWG.Name | E2: จำนวนชิ้น | F2: เสร็จแล้ว | G2: ยังไม่เสร็จ | H2: สถานะ | I2: Machine | J2: ผู้รับผิดชอบ | K2: โปรแกรม | L2: ผู้ส่งแบบ | M2: กำหนดส่ง | N2: วันเสร็จจริง | O2: ผู้รับ | P2: วันที่รับ | Q2: KPI ส่งมอบ | R2: แก้ไข(ชิ้น) | S2: Remark
A3: 1 | B3: 12 | G3: =$E3-$F3 -> 0 | H3: =IF($G3=0,"ครบ","ไม่ครบ") -> ครบ | J3: =VLOOKUP(I3,Sheet2!$B$1:$C$62,2,FALSE) -> #N/A | K3: =VLOOKUP(J3,Sheet2!$C$1:$D$61,2,FALSE) -> #N/A | Q3: =IF($N3>$M3,"เกินกำหนด","ทันกำหนด") -> ทันกำหนด
A4: 2 | G4: =$E4-$F4 -> 0 | H4: =IF($G4=0,"ครบ","ไม่ครบ") -> ครบ | J4: =VLOOKUP(I4,Sheet2!$B$1:$C$62,2,FALSE) -> #N/A | K4: =VLOOKUP(J4,Sheet2!$C$1:$D$61,2,FALSE) -> #N/A | Q4: =IF($N4>$M4,"เกินกำหนด","ทันกำหนด") -> ทันกำหนด
A5: 3 | G5: =$E5-$F5 -> 0 | H5: =IF($G5=0,"ครบ","ไม่ครบ") -> ครบ | J5: =VLOOKUP(I5,Sheet2!$B$1:$C$62,2,FALSE) -> #N/A | K5: =VLOOKUP(J5,Sheet2!$C$1:$D$61,2,FALSE) -> #N/A | Q5: =IF($N5>$M5,"เกินกำหนด","ทันกำหนด") -> ทันกำหนด
A6: 4 | G6: =$E6-$F6 -> 0 | H6: =IF($G6=0,"ครบ","ไม่ครบ") -> ครบ | J6: =VLOOKUP(I6,Sheet2!$B$1:$C$62,2,FALSE) -> #N/A | K6: =VLOOKUP(J6,Sheet2!$C$1:$D$61,2,FALSE) -> #N/A | Q6: =IF($N6>$M6,"เกินกำหนด","ทันกำหนด") -> ทันกำหนด
A7: 5 | G7: =$E7-$F7 -> 0 | H7: =IF($G7=0,"ครบ","ไม่ครบ") -> ครบ | J7: =VLOOKUP(I7,Sheet2!$B$1:$C$62,2,FALSE) -> #N/A | K7: =VLOOKUP(J7,Sheet2!$C$1:$D$61,2,FALSE) -> #N/A | Q7: =IF($N7>$M7,"เกินกำหนด","ทันกำหนด") -> ทันกำหนด
A8: 6 | G8: =$E8-$F8 -> 0 | H8: =IF($G8=0,"ครบ","ไม่ครบ") -> ครบ | J8: =VLOOKUP(I8,Sheet2!$B$1:$C$62,2,FALSE) -> #N/A | K8: =VLOOKUP(J8,Sheet2!$C$1:$D$61,2,FALSE) -> #N/A | Q8: =IF($N8>$M8,"เกินกำหนด","ทันกำหนด") -> ทันกำหนด
A9: 7 | G9: =$E9-$F9 -> 0 | H9: =IF($G9=0,"ครบ","ไม่ครบ") -> ครบ | J9: =VLOOKUP(I9,Sheet2!$B$1:$C$62,2,FALSE) -> #N/A | K9: =VLOOKUP(J9,Sheet2!$C$1:$D$61,2,FALSE) -> #N/A | Q9: =IF($N9>$M9,"เกินกำหนด","ทันกำหนด") -> ทันกำหนด
A10: 8 | G10: =$E10-$F10 -> 0 | H10: =IF($G10=0,"ครบ","ไม่ครบ") -> ครบ | J10: =VLOOKUP(I10,Sheet2!$B$1:$C$62,2,FALSE) -> #N/A | K10: =VLOOKUP(J10,Sheet2!$C$1:$D$61,2,FALSE) -> #N/A | Q10: =IF($N10>$M10,"เกินกำหนด","ทันกำหนด") -> ทันกำหนด
A11: 9 | G11: =$E11-$F11 -> 0 | H11: =IF($G11=0,"ครบ","ไม่ครบ") -> ครบ | J11: =VLOOKUP(I11,Sheet2!$B$1:$C$62,2,FALSE) -> #N/A | K11: =VLOOKUP(J11,Sheet2!$C$1:$D$61,2,FALSE) -> #N/A | Q11: =IF($N11>$M11,"เกินกำหนด","ทันกำหนด") -> ทันกำหนด
A12: 10 | G12: =$E12-$F12 -> 0 | H12: =IF($G12=0,"ครบ","ไม่ครบ") -> ครบ | J12: =VLOOKUP(I12,Sheet2!$B$1:$C$62,2,FALSE) -> #N/A | K12: =VLOOKUP(J12,Sheet2!$C$1:$D$61,2,FALSE) -> #N/A | Q12: =IF($N12>$M12,"เกินกำหนด","ทันกำหนด") -> ทันกำหนด
A13: 11 | G13: =$E13-$F13 -> 0 | H13: =IF($G13=0,"ครบ","ไม่ครบ") -> ครบ | J13: =VLOOKUP(I13,Sheet2!$B$1:$C$62,2,FALSE) -> #N/A | K13: =VLOOKUP(J13,Sheet2!$C$1:$D$61,2,FALSE) -> #N/A | Q13: =IF($N13>$M13,"เกินกำหนด","ทันกำหนด") -> ทันกำหนด
A14: 12 | G14: =$E14-$F14 -> 0 | H14: =IF($G14=0,"ครบ","ไม่ครบ") -> ครบ | J14: =VLOOKUP(I14,Sheet2!$B$1:$C$62,2,FALSE) -> #N/A | K14: =VLOOKUP(J14,Sheet2!$C$1:$D$61,2,FALSE) -> #N/A | Q14: =IF($N14>$M14,"เกินกำหนด","ทันกำหนด") -> ทันกำหนด
A15: 13 | G15: =$E15-$F15 -> 0 | H15: =IF($G15=0,"ครบ","ไม่ครบ") -> ครบ | J15: =VLOOKUP(I15,Sheet2!$B$1:$C$62,2,FALSE) -> #N/A | K15: =VLOOKUP(J15,Sheet2!$C$1:$D$61,2,FALSE) -> #N/A | Q15: =IF($N15>$M15,"เกินกำหนด","ทันกำหนด") -> ทันกำหนด
... A39: 37 | G39: =$E39-$F39 -> 0 | H39: =IF($G39=0,"ครบ","ไม่ครบ") -> ครบ | J39: =VLOOKUP(I39,Sheet2!$B$1:$C$62,2,FALSE) -> #N/A | K39: =VLOOKUP(J39,Sheet2!$C$1:$D$61,2,FALSE) -> #N/A | Q39: =IF($N39>$M39,"เกินกำหนด","ทันกำหนด") -> ทันกำหนด
A40: 38 | G40: =$E40-$F40 -> 0 | H40: =IF($G40=0,"ครบ","ไม่ครบ") -> ครบ | J40: =VLOOKUP(I40,Sheet2!$B$1:$C$62,2,FALSE) -> #N/A | K40: =VLOOKUP(J40,Sheet2!$C$1:$D$61,2,FALSE) -> #N/A | Q40: =IF($N40>$M40,"เกินกำหนด","ทันกำหนด") -> ทันกำหนด | R40: 1 | S40: งานแก้
A41: 39 | G41: =$E41-$F41 -> 0 | H41: =IF($G41=0,"ครบ","ไม่ครบ") -> ครบ | J41: =VLOOKUP(I41,Sheet2!$B$1:$C$62,2,FALSE) -> #N/A | K41: =VLOOKUP(J41,Sheet2!$C$1:$D$61,2,FALSE) -> #N/A | Q41: =IF($N41>$M41,"เกินกำหนด","ทันกำหนด") -> ทันกำหนด
A42: 40 | G42: =$E42-$F42 -> 0 | H42: =IF($G42=0,"ครบ","ไม่ครบ") -> ครบ | J42: =VLOOKUP(I42,Sheet2!$B$1:$C$62,2,FALSE) -> #N/A | K42: =VLOOKUP(J42,Sheet2!$C$1:$D$61,2,FALSE) -> #N/A | Q42: =IF($N42>$M42,"เกินกำหนด","ทันกำหนด") -> ทันกำหนด
A43: 41 | G43: =$E43-$F43 -> 0 | H43: =IF($G43=0,"ครบ","ไม่ครบ") -> ครบ | J43: =VLOOKUP(I43,Sheet2!$B$1:$C$62,2,FALSE) -> #N/A | K43: =VLOOKUP(J43,Sheet2!$C$1:$D$61,2,FALSE) -> #N/A | Q43: =IF($N43>$M43,"เกินกำหนด","ทันกำหนด") -> ทันกำหนด
A44: 42 | G44: =$E44-$F44 -> 0 | H44: =IF($G44=0,"ครบ","ไม่ครบ") -> ครบ | J44: =VLOOKUP(I44,Sheet2!$B$1:$C$62,2,FALSE) -> #N/A | K44: =VLOOKUP(J44,Sheet2!$C$1:$D$61,2,FALSE) -> #N/A | Q44: =IF($N44>$M44,"เกินกำหนด","ทันกำหนด") -> ทันกำหนด
A45: 43 | G45: =$E45-$F45 -> 0 | H45: =IF($G45=0,"ครบ","ไม่ครบ") -> ครบ | J45: =VLOOKUP(I45,Sheet2!$B$1:$C$62,2,FALSE) -> #N/A | K45: =VLOOKUP(J45,Sheet2!$C$1:$D$61,2,FALSE) -> #N/A | Q45: =IF($N45>$M45,"เกินกำหนด","ทันกำหนด") -> ทันกำหนด
A46: 44 | G46: =$E46-$F46 -> 0 | H46: =IF($G46=0,"ครบ","ไม่ครบ") -> ครบ | J46: =VLOOKUP(I46,Sheet2!$B$1:$C$62,2,FALSE) -> #N/A | K46: =VLOOKUP(J46,Sheet2!$C$1:$D$61,2,FALSE) -> #N/A | Q46: =IF($N46>$M46,"เกินกำหนด","ทันกำหนด") -> ทันกำหนด
A47: 45 | G47: =$E47-$F47 -> 0 | H47: =IF($G47=0,"ครบ","ไม่ครบ") -> ครบ | J47: =VLOOKUP(I47,Sheet2!$B$1:$C$62,2,FALSE) -> #N/A | K47: =VLOOKUP(J47,Sheet2!$C$1:$D$61,2,FALSE) -> #N/A | Q47: =IF($N47>$M47,"เกินกำหนด","ทันกำหนด") -> ทันกำหนด
A48: 46 | G48: =$E48-$F48 -> 0 | H48: =IF($G48=0,"ครบ","ไม่ครบ") -> ครบ | J48: =VLOOKUP(I48,Sheet2!$B$1:$C$62,2,FALSE) -> #N/A | K48: =VLOOKUP(J48,Sheet2!$C$1:$D$61,2,FALSE) -> #N/A | Q48: =IF($N48>$M48,"เกินกำหนด","ทันกำหนด") -> ทันกำหนด
A49: 47 | G49: =$E49-$F49 -> 0 | H49: =IF($G49=0,"ครบ","ไม่ครบ") -> ครบ | J49: =VLOOKUP(I49,Sheet2!$B$1:$C$62,2,FALSE) -> #N/A | K49: =VLOOKUP(J49,Sheet2!$C$1:$D$61,2,FALSE) -> #N/A | Q49: =IF($N49>$M49,"เกินกำหนด","ทันกำหนด") -> ทันกำหนด
A50: 48 | G50: =$E50-$F50 -> 0 | H50: =IF($G50=0,"ครบ","ไม่ครบ") -> ครบ | J50: =VLOOKUP(I50,Sheet2!$B$1:$C$62,2,FALSE) -> #N/A | K50: =VLOOKUP(J50,Sheet2!$C$1:$D$61,2,FALSE) -> #N/A | Q50: =IF($N50>$M50,"เกินกำหนด","ทันกำหนด") -> ทันกำหนด
A51: 49 | G51: =$E51-$F51 -> 0 | H51: =IF($G51=0,"ครบ","ไม่ครบ") -> ครบ | J51: =VLOOKUP(I51,Sheet2!$B$1:$C$62,2,FALSE) -> #N/A | K51: =VLOOKUP(J51,Sheet2!$C$1:$D$61,2,FALSE) -> #N/A | Q51: =IF($N51>$M51,"เกินกำหนด","ทันกำหนด") -> ทันกำหนด
A52: 50 | G52: =$E52-$F52 -> 0 | H52: =IF($G52=0,"ครบ","ไม่ครบ") -> ครบ | J52: =VLOOKUP(I52,Sheet2!$B$1:$C$62,2,FALSE) -> #N/A | K52: =VLOOKUP(J52,Sheet2!$C$1:$D$61,2,FALSE) -> #N/A | Q52: =IF($N52>$M52,"เกินกำหนด","ทันกำหนด") -> ทันกำหนด | R52: 1 | S52: งานแก้
A53: 51 | G53: =$E53-$F53 -> 0 | H53: =IF($G53=0,"ครบ","ไม่ครบ") -> ครบ | J53: =VLOOKUP(I53,Sheet2!$B$1:$C$62,2,FALSE) -> #N/A | K53: =VLOOKUP(J53,Sheet2!$C$1:$D$61,2,FALSE) -> #N/A | Q53: =IF($N53>$M53,"เกินกำหนด","ทันกำหนด") -> ทันกำหนด
A54: 52 | G54: =$E54-$F54 -> 0 | H54: =IF($G54=0,"ครบ","ไม่ครบ") -> ครบ | J54: =VLOOKUP(I54,Sheet2!$B$1:$C$62,2,FALSE) -> #N/A | K54: =VLOOKUP(J54,Sheet2!$C$1:$D$61,2,FALSE) -> #N/A | Q54: =IF($N54>$M54,"เกินกำหนด","ทันกำหนด") -> ทันกำหนด
A55: 53 | G55: =$E55-$F55 -> 0 | H55: =IF($G55=0,"ครบ","ไม่ครบ") -> ครบ | J55: =VLOOKUP(I55,Sheet2!$B$1:$C$62,2,FALSE) -> #N/A | K55: =VLOOKUP(J55,Sheet2!$C$1:$D$61,2,FALSE) -> #N/A | Q55: =IF($N55>$M55,"เกินกำหนด","ทันกำหนด") -> ทันกำหนด
A56: 54 | G56: =$E56-$F56 -> 0 | H56: =IF($G56=0,"ครบ","ไม่ครบ") -> ครบ | J56: =VLOOKUP(I56,Sheet2!$B$1:$C$62,2,FALSE) -> #N/A | K56: =VLOOKUP(J56,Sheet2!$C$1:$D$61,2,FALSE) -> #N/A | Q56: =IF($N56>$M56,"เกินกำหนด","ทันกำหนด") -> ทันกำหนด
A57: 55 | G57: =$E57-$F57 -> 0 | H57: =IF($G57=0,"ครบ","ไม่ครบ") -> ครบ | J57: =VLOOKUP(I57,Sheet2!$B$1:$C$62,2,FALSE) -> #N/A | K57: =VLOOKUP(J57,Sheet2!$C$1:$D$61,2,FALSE) -> #N/A | Q57: =IF($N57>$M57,"เกินกำหนด","ทันกำหนด") -> ทันกำหนด
A58: 56 | G58: =$E58-$F58 -> 0 | H58: =IF($G58=0,"ครบ","ไม่ครบ") -> ครบ | J58: =VLOOKUP(I58,Sheet2!$B$1:$C$62,2,FALSE) -> #N/A | K58: =VLOOKUP(J58,Sheet2!$C$1:$D$61,2,FALSE) -> #N/A | Q58: =IF($N58>$M58,"เกินกำหนด","ทันกำหนด") -> ทันกำหนด
A59: 57 | G59: =$E59-$F59 -> 0 | H59: =IF($G59=0,"ครบ","ไม่ครบ") -> ครบ | J59: =VLOOKUP(I59,Sheet2!$B$1:$C$62,2,FALSE) -> #N/A | K59: =VLOOKUP(J59,Sheet2!$C$1:$D$61,2,FALSE) -> #N/A | Q59: =IF($N59>$M59,"เกินกำหนด","ทันกำหนด") -> ทันกำหนด
A60: 58 | G60: =$E60-$F60 -> 0 | H60: =IF($G60=0,"ครบ","ไม่ครบ") -> ครบ | J60: =VLOOKUP(I60,Sheet2!$B$1:$C$62,2,FALSE) -> #N/A | K60: =VLOOKUP(J60,Sheet2!$C$1:$D$61,2,FALSE) -> #N/A | Q60: =IF($N60>$M60,"เกินกำหนด","ทันกำหนด") -> ทันกำหนด
A61: 59 | G61: =$E61-$F61 -> 0 | H61: =IF($G61=0,"ครบ","ไม่ครบ") -> ครบ | J61: =VLOOKUP(I61,Sheet2!$B$1:$C$62,2,FALSE) -> #N/A | K61: =VLOOKUP(J61,Sheet2!$C$1:$D$61,2,FALSE) -> #N/A | Q61: =IF($N61>$M61,"เกินกำหนด","ทันกำหนด") -> ทันกำหนด
A62: 60 | G62: =$E62-$F62 -> 0 | H62: =IF($G62=0,"ครบ","ไม่ครบ") -> ครบ | J62: =VLOOKUP(I62,Sheet2!$B$1:$C$62,2,FALSE) -> #N/A | K62: =VLOOKUP(J62,Sheet2!$C$1:$D$61,2,FALSE) -> #N/A | Q62: =IF($N62>$M62,"เกินกำหนด","ทันกำหนด") -> ทันกำหนด
A63: 61 | G63: =$E63-$F63 -> 0 | H63: =IF($G63=0,"ครบ","ไม่ครบ") -> ครบ | J63: =VLOOKUP(I63,Sheet2!$B$1:$C$62,2,FALSE) -> #N/A | K63: =VLOOKUP(J63,Sheet2!$C$1:$D$61,2,FALSE) -> #N/A | Q63: =IF($N63>$M63,"เกินกำหนด","ทันกำหนด") -> ทันกำหนด
...

Sheet Sheet2
B1: CAM 1 | C1: ศักดิ์ดา | D1: Grinding | E1: C/A
B2: CAM 2 | C2: สุขสันต์ | D2: Wire cut | E2: ชุบแข็ง
B3: ML 1 | C3: จักรกฤษณ์ | D3: Waterjet | E3: ZINC
B4: ML 2 | C4: องอาจ | D4: EDM | E4: H/C
B5: ML 3 | C5: สรายุทธ | D5: CNC-Late | E5: E/N
B6: LATHE 1 | C6: ชาญชัย | D6: Weldding | E6: B/O
B7: LATHE 2 | C7: สรายุทธ | E7: B/A
B8: SPAR | C8: ธีรณัฐ
B10: CAM 1 | C10: เพลินชัย
B11: CAM 2 | C11: สุขสันต์
B12: CAM 3 | C12: รังสรรค์
B13: ML 1 | C13: จักรกฤษณ์
B14: ML 2 | C14: องอาจ
B15: ML 3 | C15: สรายุทธ
B16: LATHE 1 | C16: ชาญชัย
B17: LATHE 2 | C17: สรายุทธ
B18: SPAR | C18: ธีรณัฐ
